<sdf version='1.7'>
  <world name='default'>
    <light name='sun' type='directional'>
      <cast_shadows>1</cast_shadows>
      <pose>0 0 10 0 -0 0</pose>
      <diffuse>0.8 0.8 0.8 1</diffuse>
      <specular>0.2 0.2 0.2 1</specular>
      <attenuation>
        <range>1000</range>
        <constant>0.9</constant>
        <linear>0.01</linear>
        <quadratic>0.001</quadratic>
      </attenuation>
      <direction>-0.5 0.1 -0.9</direction>
      <spot>
        <inner_angle>0</inner_angle>
        <outer_angle>0</outer_angle>
        <falloff>0</falloff>
      </spot>
    </light>
    <model name='ground_plane'>
      <static>1</static>
      <link name='link'>
        <collision name='collision'>
          <geometry>
            <plane>
              <normal>0 0 1</normal>
              <size>100 100</size>
            </plane>
          </geometry>
          <surface>
            <friction>
              <ode>
                <mu>100</mu>
                <mu2>50</mu2>
              </ode>
              <torsional>
                <ode/>
              </torsional>
            </friction>
            <contact>
              <ode/>
            </contact>
            <bounce/>
          </surface>
          <max_contacts>10</max_contacts>
        </collision>
        <visual name='visual'>
          <cast_shadows>0</cast_shadows>
          <geometry>
            <plane>
              <normal>0 0 1</normal>
              <size>100 100</size>
            </plane>
          </geometry>
          <material>
            <script>
              <uri>file://media/materials/scripts/gazebo.material</uri>
              <name>Gazebo/Grey</name>
            </script>
          </material>
        </visual>
        <self_collide>0</self_collide>
        <enable_wind>0</enable_wind>
        <kinematic>0</kinematic>
      </link>
    </model>
    <gravity>0 0 -9.8</gravity>
    <magnetic_field>6e-06 2.3e-05 -4.2e-05</magnetic_field>
    <atmosphere type='adiabatic'/>
    <physics type='ode'>
      <max_step_size>0.01</max_step_size>
      <real_time_factor>1</real_time_factor>
      <real_time_update_rate>100</real_time_update_rate>
    </physics>
    <scene>
      <ambient>0.4 0.4 0.4 1</ambient>
      <background>0.7 0.7 0.7 1</background>
      <shadows>1</shadows>
    </scene>
    <wind/>
    <spherical_coordinates>
      <surface_model>EARTH_WGS84</surface_model>
      <latitude_deg>0</latitude_deg>
      <longitude_deg>0</longitude_deg>
      <elevation>0</elevation>
      <heading_deg>0</heading_deg>
    </spherical_coordinates>
    <state world_name='default'>
      <sim_time>283211 696000000</sim_time>
      <real_time>157 343460101</real_time>
      <wall_time>1709214182 198866584</wall_time>
      <iterations>9414</iterations>
      <model name='car1'>
        <pose>-7.84304 7.8682 0.290336 -0.000179 0.008178 -0.067654</pose>
        <scale>1 1 1</scale>
        <link name='base_link'>
          <pose>-7.84304 7.8682 0.290336 -0.000179 0.008178 -0.067654</pose>
          <velocity>-0.000386 -0.000152 -0.087272 3.7e-05 0.001514 -0.000929</velocity>
          <acceleration>0.005402 0.013744 -9.80011 -0.084174 -0.013707 0.047477</acceleration>
          <wrench>0.089615 0.22801 -162.583 0 -0 0</wrench>
        </link>
        <link name='fr_left_link'>
          <pose>-7.48785 8.09088 0.133881 1.57082 -0.115569 -0.050265</pose>
          <velocity>-0.0005 -0.000937 -0.084508 -0.001062 0.001759 0.040658</velocity>
          <acceleration>-0.030378 -0.037497 -9.46946 -0.256711 0.012976 -0.028796</acceleration>
          <wrench>-0.030378 -0.037497 -9.46946 0 -0 0</wrench>
        </link>
        <link name='fr_right_link'>
          <pose>-7.51954 7.59952 0.134217 1.57165 1.38639 3.07526</pose>
          <velocity>-0.000722 -0.000858 -0.091016 -9.3e-05 0.00172 0.047984</velocity>
          <acceleration>0.038714 -0.051454 -10.1317 -0.188378 0.013161 -0.02681</acceleration>
          <wrench>0.038714 -0.051454 -10.1317 0 -0 0</wrench>
        </link>
        <link name='fr_steer_left_link'>
          <pose>-7.48785 8.09088 0.13394 -0.000159 0.008178 -0.067239</pose>
          <velocity>-0.000594 -0.000869 -0.085992 -3.6e-05 0.001521 0.040645</velocity>
          <acceleration>-0.039762 -0.030739 -9.61621 -0.15402 -0.01073 -0.017696</acceleration>
          <wrench>-0.039762 -0.030739 -9.61621 0 -0 0</wrench>
        </link>
        <link name='fr_steer_right_link'>
          <pose>-7.51953 7.59953 0.134159 -0.000105 0.00812 -0.067178</pose>
          <velocity>-0.000992 -0.001167 -0.089578 -0.001208 0.003057 0.047999</velocity>
          <acceleration>0.011707 -0.082275 -9.98589 -0.299967 0.147222 -0.013291</acceleration>
          <wrench>0.011707 -0.082275 -9.98589 0 -0 0</wrench>
        </link>
        <link name='front_steer_link'>
          <pose>-7.43674 7.84067 0.201167 -0.008995 0.00848 -0.621268</pose>
          <velocity>-0.001015 -0.00146 -0.077123 0.131854 -0.157141 0.855113</velocity>
          <acceleration>-0.197753 0.125263 -7.51399 0.871547 -0.792451 1.82888</acceleration>
          <wrench>-0.000973 0.000616 -0.036953 0 -0 0</wrench>
        </link>
        <link name='re_left_link'>
          <pose>-8.0346 8.13373 0.134112 -1.57073 -0.29215 3.07395</pose>
          <velocity>-0.000544 -3.4e-05 -0.089867 -0.002824 0.001914 -0.001722</velocity>
          <acceleration>-0.021074 -0.019059 -10.1195 -0.370493 0.025088 -0.054097</acceleration>
          <wrench>-0.021074 -0.019059 -10.1195 0 -0 0</wrench>
        </link>
        <link name='re_right_link'>
          <pose>-8.06865 7.63088 0.133967 -1.57104 -1.36711 -0.067387</pose>
          <velocity>-0.001511 0.000103 -0.08396 -0.003273 0.001944 -0.00162</velocity>
          <acceleration>-0.047455 -0.010189 -9.48632 -0.415389 0.028129 -0.036693</acceleration>
          <wrench>-0.047455 -0.010189 -9.48632 0 -0 0</wrench>
        </link>
        <link name='rear_wheel_link'>
          <pose>-8.14714 7.88863 0.207265 0.006215 -0.006208 1.90496</pose>
          <velocity>0.000176 0.002291 -0.087575 0.018478 -0.012491 -2.85768</velocity>
          <acceleration>-0.080037 0.526047 -9.88372 -1.60324 -0.490943 0.207649</acceleration>
          <wrench>-0.000394 0.002587 -0.048607 0 -0 0</wrench>
        </link>
      </model>
      <model name='car2'>
        <pose>-7.42398 -7.76921 0.291247 -0.000457 0.008335 0.152541</pose>
        <scale>1 1 1</scale>
        <link name='base_link'>
          <pose>-7.42398 -7.76921 0.291247 -0.000457 0.008335 0.152541</pose>
          <velocity>-0.000719 -0.000467 0.012069 0.00166 0.0017 0.002777</velocity>
          <acceleration>-0.055032 0.014677 9.80895 -0.010969 0.025979 -0.009043</acceleration>
          <wrench>-0.912983 0.243491 162.729 0 -0 0</wrench>
        </link>
        <link name='fr_left_link'>
          <pose>-7.12602 -7.47438 0.134695 1.57044 -0.197498 0.16881</pose>
          <velocity>-0.004516 -0.000257 0.013042 -0.003208 -0.01591 -0.109235</velocity>
          <acceleration>-0.310157 -0.054809 9.77119 -0.55952 -1.06166 -1.07112</acceleration>
          <wrench>-0.310157 -0.054809 9.77119 0 -0 0</wrench>
        </link>
        <link name='fr_right_link'>
          <pose>-7.04961 -7.96081 0.135117 1.57391 1.3911 -2.98569</pose>
          <velocity>-0.00113 2e-06 0.010117 -0.000501 -0.00425 0.033542</velocity>
          <acceleration>-0.126074 -0.027778 9.8236 -0.214021 -0.401994 -0.236743</acceleration>
          <wrench>-0.126074 -0.027778 9.8236 0 -0 0</wrench>
        </link>
        <link name='fr_steer_left_link'>
          <pose>-7.12602 -7.47438 0.134743 -0.00048 0.008335 0.151763</pose>
          <velocity>-0.002768 0.000288 0.012655 -0.002441 0.000971 -0.110887</velocity>
          <acceleration>-0.13268 8e-05 9.73833 -0.366868 -0.032606 -0.792764</acceleration>
          <wrench>-0.13268 8e-05 9.73833 0 -0 0</wrench>
        </link>
        <link name='fr_steer_right_link'>
          <pose>-7.04961 -7.96078 0.135071 -0.000423 0.008289 0.152836</pose>
          <velocity>-0.000576 0.000407 0.010577 0.000978 0.001642 0.03352</velocity>
          <acceleration>-0.070837 0.012763 9.86573 -0.026277 -0.06601 -0.140982</acceleration>
          <wrench>-0.070837 0.012763 9.86573 0 -0 0</wrench>
        </link>
        <link name='front_steer_link'>
          <pose>-7.02149 -7.70736 0.201918 0.008129 0.009193 0.539334</pose>
          <velocity>-0.000888 0.000727 0.00466 0.071923 0.068946 -0.483121</velocity>
          <acceleration>0.146536 -0.065888 7.8152 2.01917 -0.377377 2.76378</acceleration>
          <wrench>0.000721 -0.000324 0.038434 0 -0 0</wrench>
        </link>
        <link name='re_left_link'>
          <pose>-7.66893 -7.55197 0.134971 -1.57029 -0.795175 -2.98938</pose>
          <velocity>-0.001079 -0.000766 0.011981 0.0057 -0.008083 0.002828</velocity>
          <acceleration>-0.00643 0.02779 9.73055 0.328335 -0.543814 -0.008282</acceleration>
          <wrench>-0.00643 0.02779 9.73055 0 -0 0</wrench>
        </link>
        <link name='re_right_link'>
          <pose>-7.59235 -8.05012 0.134997 -1.57121 -0.585909 0.152787</pose>
          <velocity>0.001395 -0.000226 0.012524 0.001318 0.010616 0.003774</velocity>
          <acceleration>0.097689 0.059762 9.88249 0.010372 0.544822 0.153101</acceleration>
          <wrench>0.097689 0.059762 9.88249 0 -0 0</wrench>
        </link>
        <link name='rear_wheel_link'>
          <pose>-7.72507 -7.81561 0.208233 -0.000442 -0.00914 3.01784</pose>
          <velocity>0.001137 0.000844 0.012759 0.00328 0.004803 0.69729</velocity>
          <acceleration>0.273325 -0.009744 9.89807 -0.24746 1.25684 1.98514</acceleration>
          <wrench>0.001344 -4.8e-05 0.048678 0 -0 0</wrench>
        </link>
      </model>
      <model name='car3'>
        <pose>8.14953 7.95486 0.29118 -0.000362 0.008061 3.01736</pose>
        <scale>1 1 1</scale>
        <link name='base_link'>
          <pose>8.14953 7.95486 0.29118 -0.000362 0.008061 3.01736</pose>
          <velocity>0.001826 0.000933 0.010634 -0.001573 0.001498 -0.00695</velocity>
          <acceleration>0.03559 -0.011076 9.79575 -0.134238 -0.139166 0.237574</acceleration>
          <wrench>0.590442 -0.183756 162.51 0 -0 0</wrench>
        </link>
        <link name='fr_left_link'>
          <pose>7.78198 7.7527 0.134797 1.57065 0.008502 3.03802</pose>
          <velocity>0.00523 0.003332 0.010731 0.011968 0.111555 0.49811</velocity>
          <acceleration>1.24601 -1.05776 9.46325 2.26663 0.537003 1.27626</acceleration>
          <wrench>1.24601 -1.05776 9.46325 0 -0 0</wrench>
        </link>
        <link name='fr_right_link'>
          <pose>7.84174 8.24136 0.135127 1.57084 1.39372 -0.123474</pose>
          <velocity>0.003643 0.001376 0.010506 -0.010658 0.017974 0.071522</velocity>
          <acceleration>-0.01367 -0.342318 9.81643 -1.30669 1.01018 -0.165661</acceleration>
          <wrench>-0.01367 -0.342318 9.81643 0 -0 0</wrench>
        </link>
        <link name='fr_steer_left_link'>
          <pose>7.78263 7.75217 0.134698 0.002315 0.008095 3.02158</pose>
          <velocity>-0.005042 0.011214 0.013083 0.03839 -0.001864 0.495622</velocity>
          <acceleration>0.214809 -0.269088 9.63623 -0.946523 -0.050728 0.497937</acceleration>
          <wrench>0.214809 -0.269088 9.63623 0 -0 0</wrench>
        </link>
        <link name='fr_steer_right_link'>
          <pose>7.84172 8.24139 0.13507 -0.000191 0.008037 3.01808</pose>
          <velocity>0.003726 0.002751 0.010612 -0.004335 0.002066 0.071481</velocity>
          <acceleration>-0.004897 -0.204505 9.84051 -0.602923 0.006477 -0.103453</acceleration>
          <wrench>-0.004897 -0.204505 9.84051 0 -0 0</wrench>
        </link>
        <link name='front_steer_link'>
          <pose>7.74546 8.0053 0.202008 0.007166 0.007469 -2.74219</pose>
          <velocity>0.001818 0.004062 0.006767 -0.032868 -0.01101 -0.789381</velocity>
          <acceleration>-0.040031 0.108287 8.42344 0.42276 0.073416 0.192784</acceleration>
          <wrench>-0.000197 0.000533 0.041426 0 -0 0</wrench>
        </link>
        <link name='re_left_link'>
          <pose>8.32587 7.67896 0.134909 -1.55493 -1.55377 -0.14</pose>
          <velocity>-0.002546 5e-05 0.010162 -0.000379 -0.019622 -0.00759</velocity>
          <acceleration>-0.107759 0.085284 9.77911 0.164753 -1.33417 0.233356</acceleration>
          <wrench>-0.107759 0.085284 9.77911 0 -0 0</wrench>
        </link>
        <link name='re_right_link'>
          <pose>8.38818 8.17908 0.134823 -1.57115 -0.538908 3.01759</pose>
          <velocity>0.003819 -0.000676 0.010321 0.004798 0.028924 -0.007289</velocity>
          <acceleration>0.079266 0.068759 9.86053 0.432706 1.52083 0.284052</acceleration>
          <wrench>0.079266 0.068759 9.86053 0 -0 0</wrench>
        </link>
        <link name='rear_wheel_link'>
          <pose>8.45178 7.91695 0.208102 -0.007836 -0.00427 0.673805</pose>
          <velocity>-0.002144 -0.004232 0.011171 -0.008625 -0.003657 1.55712</velocity>
          <acceleration>-0.396321 -0.191343 9.99003 -1.51519 -0.703322 -1.02653</acceleration>
          <wrench>-0.001949 -0.000941 0.04913 0 -0 0</wrench>
        </link>
      </model>
      <model name='car4'>
        <pose>8.38799 -8.13745 0.291091 6.2e-05 0.008665 -3.08818</pose>
        <scale>1 1 1</scale>
        <link name='base_link'>
          <pose>8.38799 -8.13745 0.291091 6.2e-05 0.008665 -3.08818</pose>
          <velocity>-0.018036 0.002856 0.004967 -0.021097 -0.00754 -0.00634</velocity>
          <acceleration>-0.653742 3.57984 4.29697 1.28091 -0.933374 -2.114</acceleration>
          <wrench>-10.8455 59.3892 71.2863 0 -0 0</wrench>
        </link>
        <link name='fr_left_link'>
          <pose>8.06252 -8.40067 0.134837 1.5663 0.172291 -3.0697</pose>
          <velocity>-0.020319 -0.000462 0.009909 -0.030785 -0.105969 0.331566</velocity>
          <acceleration>-0.031069 0.093957 9.47567 0.795425 -0.861896 2.47956</acceleration>
          <wrench>-0.031069 0.093957 9.47567 0 -0 0</wrench>
        </link>
        <link name='fr_right_link'>
          <pose>8.03451 -7.91031 0.134713 1.56776 -0.278793 0.055192</pose>
          <velocity>-0.016429 0.012823 -0.006236 0.046493 0.003859 0.177117</velocity>
          <acceleration>-0.989196 1.24031 -1.61466 2.06016 -0.527873 -0.922373</acceleration>
          <wrench>-0.989196 1.24031 -1.61466 0 -0 0</wrench>
        </link>
        <link name='fr_steer_left_link'>
          <pose>8.06245 -8.40127 0.134747 -0.000969 0.008647 -3.08581</pose>
          <velocity>-0.018953 0.001908 0.009421 -0.023084 -0.008385 0.326805</velocity>
          <acceleration>0.097008 0.331309 9.4027 1.89375 -1.45854 0.910004</acceleration>
          <wrench>0.097008 0.331309 9.4027 0 -0 0</wrench>
        </link>
        <link name='fr_steer_right_link'>
          <pose>8.0345 -7.91003 0.134645 0.001121 0.008694 -3.0872</pose>
          <velocity>-0.016198 0.005401 -0.004797 0.001728 -0.007677 0.176416</velocity>
          <acceleration>-0.964917 0.498012 -1.54504 0.721062 -1.49335 2.47614</acceleration>
          <wrench>-0.964917 0.498012 -1.54504 0 -0 0</wrench>
        </link>
        <link name='front_steer_link'>
          <pose>7.9814 -8.15918 0.20141 -0.005575 0.007106 2.92718</pose>
          <velocity>-0.017485 0.0029 0.000524 -0.0325 0.011448 1.37498</velocity>
          <acceleration>-0.588764 0.110166 3.51403 2.45646 0.627312 1.6335</acceleration>
          <wrench>-0.002895 0.000542 0.017282 0 -0 0</wrench>
        </link>
        <link name='re_left_link'>
          <pose>8.61028 -8.37761 0.135009 -1.56424 -1.2582 0.047198</pose>
          <velocity>-0.017275 0.00036 0.011349 -0.003857 -0.128482 -0.0054</velocity>
          <acceleration>0.097637 1.09095 9.29636 -2.07476 -1.02252 -0.218058</acceleration>
          <wrench>0.097637 1.09095 9.29636 0 -0 0</wrench>
        </link>
        <link name='re_right_link'>
          <pose>8.58342 -7.8751 0.134911 -1.56806 0.278237 -3.08761</pose>
          <velocity>-0.015213 0.000559 -0.000782 -0.002663 -0.112331 -0.005152</velocity>
          <acceleration>-0.84754 1.06286 -0.740206 1.22218 -1.15903 2.94347</acceleration>
          <wrench>-0.84754 1.06286 -0.740206 0 -0 0</wrench>
        </link>
        <link name='rear_wheel_link'>
          <pose>8.69288 -8.12139 0.208215 0.004779 0.006976 -2.81165</pose>
          <velocity>-0.009297 -0.003598 0.009054 -0.045972 0.017988 -2.06839</velocity>
          <acceleration>-0.062258 -0.611007 4.56057 0.827926 1.34475 -2.39357</acceleration>
          <wrench>-0.000306 -0.003005 0.022428 0 -0 0</wrench>
        </link>
      </model>
      <model name='ground_plane'>
        <pose>0 0 0 0 -0 0</pose>
        <scale>1 1 1</scale>
        <link name='link'>
          <pose>0 0 0 0 -0 0</pose>
          <velocity>0 0 0 0 -0 0</velocity>
          <acceleration>0 0 0 0 -0 0</acceleration>
          <wrench>0 0 0 0 -0 0</wrench>
        </link>
      </model>
      <model name='unit_cylinder'>
        <pose>3.95681 -5.83359 0.499789 0.000361 0.000476 -0.135834</pose>
        <scale>1 1 1</scale>
        <link name='link'>
          <pose>3.95681 -5.83359 0.499789 0.000361 0.000476 -0.135834</pose>
          <velocity>0 0 0 0 -0 0</velocity>
          <acceleration>2.11189 -2.11212 -3.11199 1.08259 -1.08223 3.1415</acceleration>
          <wrench>2.11189 -2.11212 -3.11199 0 -0 0</wrench>
        </link>
      </model>
      <model name='unit_cylinder_0'>
        <pose>0.038353 -0.162321 0.499824 -0.000252 -0.000247 0.010179</pose>
        <scale>1 1 1</scale>
        <link name='link'>
          <pose>0.038353 -0.162321 0.499824 -0.000252 -0.000247 0.010179</pose>
          <velocity>0 0 0 0 -0 0</velocity>
          <acceleration>-4.34984 4.35027 -0.051026 0.726793 -0.72756 -3.14154</acceleration>
          <wrench>-4.34984 4.35027 -0.051026 0 -0 0</wrench>
        </link>
      </model>
      <model name='unit_cylinder_1'>
        <pose>4.0327 5.84623 0.499824 -0.000257 -0.000242 0.030026</pose>
        <scale>1 1 1</scale>
        <link name='link'>
          <pose>4.0327 5.84623 0.499824 -0.000257 -0.000242 0.030026</pose>
          <velocity>0 0 0 0 -0 0</velocity>
          <acceleration>-4.34984 4.35027 -0.051026 0.726793 -0.72756 -3.14154</acceleration>
          <wrench>-4.34984 4.35027 -0.051026 0 -0 0</wrench>
        </link>
      </model>
      <model name='unit_cylinder_10'>
        <pose>-2.9254 -5.88483 0.499789 0.000422 0.000422 -4.1e-05</pose>
        <scale>1 1 1</scale>
        <link name='link'>
          <pose>-2.9254 -5.88483 0.499789 0.000422 0.000422 -4.1e-05</pose>
          <velocity>0 0 0 0 -0 0</velocity>
          <acceleration>2.11189 -2.11212 -3.11199 1.08259 -1.08223 3.1415</acceleration>
          <wrench>2.11189 -2.11212 -3.11199 0 -0 0</wrench>
        </link>
      </model>
      <model name='unit_cylinder_2'>
        <pose>9.3976 -0.170939 0.499096 4.8e-05 4.8e-05 -6.8e-05</pose>
        <scale>1 1 1</scale>
        <link name='link'>
          <pose>9.3976 -0.170939 0.499096 4.8e-05 4.8e-05 -6.8e-05</pose>
          <velocity>0 0 0 0 -0 0</velocity>
          <acceleration>0 0 -9.8 0 -0 0</acceleration>
          <wrench>0 0 -9.8 0 -0 0</wrench>
        </link>
      </model>
      <model name='unit_cylinder_3'>
        <pose>8.85969 9.47372 0.499096 4.8e-05 4.8e-05 -5.8e-05</pose>
        <scale>1 1 1</scale>
        <link name='link'>
          <pose>8.85969 9.47372 0.499096 4.8e-05 4.8e-05 -5.8e-05</pose>
          <velocity>0 0 0 0 -0 0</velocity>
          <acceleration>0 0 -9.8 0 -0 0</acceleration>
          <wrench>0 0 -9.8 0 -0 0</wrench>
        </link>
      </model>
      <model name='unit_cylinder_4'>
        <pose>8.65917 -9.50466 0.499824 -0.000249 -0.000249 -5.6e-05</pose>
        <scale>1 1 1</scale>
        <link name='link'>
          <pose>8.65917 -9.50466 0.499824 -0.000249 -0.000249 -5.6e-05</pose>
          <velocity>0 0 0 0 -0 0</velocity>
          <acceleration>-4.34984 4.35027 -0.051026 0.726793 -0.72756 -3.14154</acceleration>
          <wrench>-4.34984 4.35027 -0.051026 0 -0 0</wrench>
        </link>
      </model>
      <model name='unit_cylinder_5'>
        <pose>-9.63957 -9.71784 0.499824 -0.000249 -0.000249 -4.6e-05</pose>
        <scale>1 1 1</scale>
        <link name='link'>
          <pose>-9.63957 -9.71784 0.499824 -0.000249 -0.000249 -4.6e-05</pose>
          <velocity>0 0 0 0 -0 0</velocity>
          <acceleration>-4.34984 4.35027 -0.051026 0.726793 -0.72756 -3.14154</acceleration>
          <wrench>-4.34984 4.35027 -0.051026 0 -0 0</wrench>
        </link>
      </model>
      <model name='unit_cylinder_6'>
        <pose>-9.50694 9.35198 0.49912 0 0 -4.6e-05</pose>
        <scale>1 1 1</scale>
        <link name='link'>
          <pose>-9.50694 9.35198 0.49912 0 0 -4.6e-05</pose>
          <velocity>0 0 0 0 -0 0</velocity>
          <acceleration>0 0 -9.8 0 -0 0</acceleration>
          <wrench>0 0 -9.8 0 -0 0</wrench>
        </link>
      </model>
      <model name='unit_cylinder_7'>
        <pose>-9.7627 -0.06869 0.499824 -0.000249 -0.000249 -4.4e-05</pose>
        <scale>1 1 1</scale>
        <link name='link'>
          <pose>-9.7627 -0.06869 0.499824 -0.000249 -0.000249 -4.4e-05</pose>
          <velocity>0 0 0 0 -0 0</velocity>
          <acceleration>-4.34984 4.35027 -0.051026 0.726793 -0.72756 -3.14154</acceleration>
          <wrench>-4.34984 4.35027 -0.051026 0 -0 0</wrench>
        </link>
      </model>
      <model name='unit_cylinder_8'>
        <pose>-3.04321 6.0655 0.49912 0 0 -4.3e-05</pose>
        <scale>1 1 1</scale>
        <link name='link'>
          <pose>-3.04321 6.0655 0.49912 0 0 -4.3e-05</pose>
          <velocity>0 0 0 0 -0 0</velocity>
          <acceleration>0 0 -9.8 0 -0 0</acceleration>
          <wrench>0 0 -9.8 0 -0 0</wrench>
        </link>
      </model>
      <light name='sun'>
        <pose>0 0 10 0 -0 0</pose>
      </light>
    </state>
    <gui fullscreen='0'>
      <camera name='user_camera'>
        <pose>-1.16139 -14.6851 29.1679 0 1.18047 1.57899</pose>
        <view_controller>orbit</view_controller>
        <projection_type>perspective</projection_type>
      </camera>
    </gui>
    <model name='unit_cylinder'>
      <pose>3.31166 3.10369 0.5 0 -0 0</pose>
      <link name='link'>
        <inertial>
          <mass>1</mass>
          <inertia>
            <ixx>0.145833</ixx>
            <ixy>0</ixy>
            <ixz>0</ixz>
            <iyy>0.145833</iyy>
            <iyz>0</iyz>
            <izz>0.125</izz>
          </inertia>
          <pose>0 0 0 0 -0 0</pose>
        </inertial>
        <collision name='collision'>
          <geometry>
            <cylinder>
              <radius>0.5</radius>
              <length>1</length>
            </cylinder>
          </geometry>
          <max_contacts>10</max_contacts>
          <surface>
            <contact>
              <ode/>
            </contact>
            <bounce/>
            <friction>
              <torsional>
                <ode/>
              </torsional>
              <ode/>
            </friction>
          </surface>
        </collision>
        <visual name='visual'>
          <geometry>
            <cylinder>
              <radius>0.5</radius>
              <length>1</length>
            </cylinder>
          </geometry>
          <material>
            <script>
              <name>Gazebo/Grey</name>
              <uri>file://media/materials/scripts/gazebo.material</uri>
            </script>
          </material>
        </visual>
        <self_collide>0</self_collide>
        <enable_wind>0</enable_wind>
        <kinematic>0</kinematic>
      </link>
    </model>
    <model name='unit_cylinder_0'>
      <pose>6.55696 1.6141 0.5 0 -0 0</pose>
      <link name='link'>
        <inertial>
          <mass>1</mass>
          <inertia>
            <ixx>0.145833</ixx>
            <ixy>0</ixy>
            <ixz>0</ixz>
            <iyy>0.145833</iyy>
            <iyz>0</iyz>
            <izz>0.125</izz>
          </inertia>
          <pose>0 0 0 0 -0 0</pose>
        </inertial>
        <collision name='collision'>
          <geometry>
            <cylinder>
              <radius>0.5</radius>
              <length>1</length>
            </cylinder>
          </geometry>
          <max_contacts>10</max_contacts>
          <surface>
            <contact>
              <ode/>
            </contact>
            <bounce/>
            <friction>
              <torsional>
                <ode/>
              </torsional>
              <ode/>
            </friction>
          </surface>
        </collision>
        <visual name='visual'>
          <geometry>
            <cylinder>
              <radius>0.5</radius>
              <length>1</length>
            </cylinder>
          </geometry>
          <material>
            <script>
              <name>Gazebo/Grey</name>
              <uri>file://media/materials/scripts/gazebo.material</uri>
            </script>
          </material>
        </visual>
        <self_collide>0</self_collide>
        <enable_wind>0</enable_wind>
        <kinematic>0</kinematic>
      </link>
    </model>
    <model name='unit_cylinder_2'>
      <pose>5.48864 -0.040205 0.5 0 -0 0</pose>
      <link name='link'>
        <inertial>
          <mass>1</mass>
          <inertia>
            <ixx>0.145833</ixx>
            <ixy>0</ixy>
            <ixz>0</ixz>
            <iyy>0.145833</iyy>
            <iyz>0</iyz>
            <izz>0.125</izz>
          </inertia>
          <pose>0 0 0 0 -0 0</pose>
        </inertial>
        <collision name='collision'>
          <geometry>
            <cylinder>
              <radius>0.5</radius>
              <length>1</length>
            </cylinder>
          </geometry>
          <max_contacts>10</max_contacts>
          <surface>
            <contact>
              <ode/>
            </contact>
            <bounce/>
            <friction>
              <torsional>
                <ode/>
              </torsional>
              <ode/>
            </friction>
          </surface>
        </collision>
        <visual name='visual'>
          <geometry>
            <cylinder>
              <radius>0.5</radius>
              <length>1</length>
            </cylinder>
          </geometry>
          <material>
            <script>
              <name>Gazebo/Grey</name>
              <uri>file://media/materials/scripts/gazebo.material</uri>
            </script>
          </material>
        </visual>
        <self_collide>0</self_collide>
        <enable_wind>0</enable_wind>
        <kinematic>0</kinematic>
      </link>
    </model>
    <model name='unit_cylinder_1'>
      <pose>-2.24978 2.29542 0.5 0 -0 0</pose>
      <link name='link'>
        <inertial>
          <mass>1</mass>
          <inertia>
            <ixx>0.145833</ixx>
            <ixy>0</ixy>
            <ixz>0</ixz>
            <iyy>0.145833</iyy>
            <iyz>0</iyz>
            <izz>0.125</izz>
          </inertia>
          <pose>0 0 0 0 -0 0</pose>
        </inertial>
        <collision name='collision'>
          <geometry>
            <cylinder>
              <radius>0.5</radius>
              <length>1</length>
            </cylinder>
          </geometry>
          <max_contacts>10</max_contacts>
          <surface>
            <contact>
              <ode/>
            </contact>
            <bounce/>
            <friction>
              <torsional>
                <ode/>
              </torsional>
              <ode/>
            </friction>
          </surface>
        </collision>
        <visual name='visual'>
          <geometry>
            <cylinder>
              <radius>0.5</radius>
              <length>1</length>
            </cylinder>
          </geometry>
          <material>
            <script>
              <name>Gazebo/Grey</name>
              <uri>file://media/materials/scripts/gazebo.material</uri>
            </script>
          </material>
        </visual>
        <self_collide>0</self_collide>
        <enable_wind>0</enable_wind>
        <kinematic>0</kinematic>
      </link>
    </model>
    <model name='unit_cylinder_3'>
      <pose>-1.78977 -0.981187 0.5 0 -0 0</pose>
      <link name='link'>
        <inertial>
          <mass>1</mass>
          <inertia>
            <ixx>0.145833</ixx>
            <ixy>0</ixy>
            <ixz>0</ixz>
            <iyy>0.145833</iyy>
            <iyz>0</iyz>
            <izz>0.125</izz>
          </inertia>
          <pose>0 0 0 0 -0 0</pose>
        </inertial>
        <collision name='collision'>
          <geometry>
            <cylinder>
              <radius>0.5</radius>
              <length>1</length>
            </cylinder>
          </geometry>
          <max_contacts>10</max_contacts>
          <surface>
            <contact>
              <ode/>
            </contact>
            <bounce/>
            <friction>
              <torsional>
                <ode/>
              </torsional>
              <ode/>
            </friction>
          </surface>
        </collision>
        <visual name='visual'>
          <geometry>
            <cylinder>
              <radius>0.5</radius>
              <length>1</length>
            </cylinder>
          </geometry>
          <material>
            <script>
              <name>Gazebo/Grey</name>
              <uri>file://media/materials/scripts/gazebo.material</uri>
            </script>
          </material>
        </visual>
        <self_collide>0</self_collide>
        <enable_wind>0</enable_wind>
        <kinematic>0</kinematic>
      </link>
    </model>
    <model name='unit_cylinder_4'>
      <pose>-3.02115 -1.07237 0.5 0 -0 0</pose>
      <link name='link'>
        <inertial>
          <mass>1</mass>
          <inertia>
            <ixx>0.145833</ixx>
            <ixy>0</ixy>
            <ixz>0</ixz>
            <iyy>0.145833</iyy>
            <iyz>0</iyz>
            <izz>0.125</izz>
          </inertia>
          <pose>0 0 0 0 -0 0</pose>
        </inertial>
        <collision name='collision'>
          <geometry>
            <cylinder>
              <radius>0.5</radius>
              <length>1</length>
            </cylinder>
          </geometry>
          <max_contacts>10</max_contacts>
          <surface>
            <contact>
              <ode/>
            </contact>
            <bounce/>
            <friction>
              <torsional>
                <ode/>
              </torsional>
              <ode/>
            </friction>
          </surface>
        </collision>
        <visual name='visual'>
          <geometry>
            <cylinder>
              <radius>0.5</radius>
              <length>1</length>
            </cylinder>
          </geometry>
          <material>
            <script>
              <name>Gazebo/Grey</name>
              <uri>file://media/materials/scripts/gazebo.material</uri>
            </script>
          </material>
        </visual>
        <self_collide>0</self_collide>
        <enable_wind>0</enable_wind>
        <kinematic>0</kinematic>
      </link>
    </model>
    <model name='unit_cylinder_5'>
      <pose>-7.55826 -2.59755 0.5 0 -0 0</pose>
      <link name='link'>
        <inertial>
          <mass>1</mass>
          <inertia>
            <ixx>0.145833</ixx>
            <ixy>0</ixy>
            <ixz>0</ixz>
            <iyy>0.145833</iyy>
            <iyz>0</iyz>
            <izz>0.125</izz>
          </inertia>
          <pose>0 0 0 0 -0 0</pose>
        </inertial>
        <collision name='collision'>
          <geometry>
            <cylinder>
              <radius>0.5</radius>
              <length>1</length>
            </cylinder>
          </geometry>
          <max_contacts>10</max_contacts>
          <surface>
            <contact>
              <ode/>
            </contact>
            <bounce/>
            <friction>
              <torsional>
                <ode/>
              </torsional>
              <ode/>
            </friction>
          </surface>
        </collision>
        <visual name='visual'>
          <geometry>
            <cylinder>
              <radius>0.5</radius>
              <length>1</length>
            </cylinder>
          </geometry>
          <material>
            <script>
              <name>Gazebo/Grey</name>
              <uri>file://media/materials/scripts/gazebo.material</uri>
            </script>
          </material>
        </visual>
        <self_collide>0</self_collide>
        <enable_wind>0</enable_wind>
        <kinematic>0</kinematic>
      </link>
    </model>
    <model name='unit_cylinder_6'>
      <pose>-12.728 -4.90877 0.5 0 -0 0</pose>
      <link name='link'>
        <inertial>
          <mass>1</mass>
          <inertia>
            <ixx>0.145833</ixx>
            <ixy>0</ixy>
            <ixz>0</ixz>
            <iyy>0.145833</iyy>
            <iyz>0</iyz>
            <izz>0.125</izz>
          </inertia>
          <pose>0 0 0 0 -0 0</pose>
        </inertial>
        <collision name='collision'>
          <geometry>
            <cylinder>
              <radius>0.5</radius>
              <length>1</length>
            </cylinder>
          </geometry>
          <max_contacts>10</max_contacts>
          <surface>
            <contact>
              <ode/>
            </contact>
            <bounce/>
            <friction>
              <torsional>
                <ode/>
              </torsional>
              <ode/>
            </friction>
          </surface>
        </collision>
        <visual name='visual'>
          <geometry>
            <cylinder>
              <radius>0.5</radius>
              <length>1</length>
            </cylinder>
          </geometry>
          <material>
            <script>
              <name>Gazebo/Grey</name>
              <uri>file://media/materials/scripts/gazebo.material</uri>
            </script>
          </material>
        </visual>
        <self_collide>0</self_collide>
        <enable_wind>0</enable_wind>
        <kinematic>0</kinematic>
      </link>
    </model>
    <model name='unit_cylinder_7'>
      <pose>-15.879 2.29168 0.5 0 -0 0</pose>
      <link name='link'>
        <inertial>
          <mass>1</mass>
          <inertia>
            <ixx>0.145833</ixx>
            <ixy>0</ixy>
            <ixz>0</ixz>
            <iyy>0.145833</iyy>
            <iyz>0</iyz>
            <izz>0.125</izz>
          </inertia>
          <pose>0 0 0 0 -0 0</pose>
        </inertial>
        <collision name='collision'>
          <geometry>
            <cylinder>
              <radius>0.5</radius>
              <length>1</length>
            </cylinder>
          </geometry>
          <max_contacts>10</max_contacts>
          <surface>
            <contact>
              <ode/>
            </contact>
            <bounce/>
            <friction>
              <torsional>
                <ode/>
              </torsional>
              <ode/>
            </friction>
          </surface>
        </collision>
        <visual name='visual'>
          <geometry>
            <cylinder>
              <radius>0.5</radius>
              <length>1</length>
            </cylinder>
          </geometry>
          <material>
            <script>
              <name>Gazebo/Grey</name>
              <uri>file://media/materials/scripts/gazebo.material</uri>
            </script>
          </material>
        </visual>
        <self_collide>0</self_collide>
        <enable_wind>0</enable_wind>
        <kinematic>0</kinematic>
      </link>
    </model>
    <model name='unit_cylinder_8'>
      <pose>-12.0474 -2.41547 0.5 0 -0 0</pose>
      <link name='link'>
        <inertial>
          <mass>1</mass>
          <inertia>
            <ixx>0.145833</ixx>
            <ixy>0</ixy>
            <ixz>0</ixz>
            <iyy>0.145833</iyy>
            <iyz>0</iyz>
            <izz>0.125</izz>
          </inertia>
          <pose>0 0 0 0 -0 0</pose>
        </inertial>
        <collision name='collision'>
          <geometry>
            <cylinder>
              <radius>0.5</radius>
              <length>1</length>
            </cylinder>
          </geometry>
          <max_contacts>10</max_contacts>
          <surface>
            <contact>
              <ode/>
            </contact>
            <bounce/>
            <friction>
              <torsional>
                <ode/>
              </torsional>
              <ode/>
            </friction>
          </surface>
        </collision>
        <visual name='visual'>
          <geometry>
            <cylinder>
              <radius>0.5</radius>
              <length>1</length>
            </cylinder>
          </geometry>
          <material>
            <script>
              <name>Gazebo/Grey</name>
              <uri>file://media/materials/scripts/gazebo.material</uri>
            </script>
          </material>
        </visual>
        <self_collide>0</self_collide>
        <enable_wind>0</enable_wind>
        <kinematic>0</kinematic>
      </link>
    </model>
    <model name='unit_cylinder_10'>
      <pose>-13.2616 6.11527 0.5 0 -0 0</pose>
      <link name='link'>
        <inertial>
          <mass>1</mass>
          <inertia>
            <ixx>0.145833</ixx>
            <ixy>0</ixy>
            <ixz>0</ixz>
            <iyy>0.145833</iyy>
            <iyz>0</iyz>
            <izz>0.125</izz>
          </inertia>
          <pose>0 0 0 0 -0 0</pose>
        </inertial>
        <collision name='collision'>
          <geometry>
            <cylinder>
              <radius>0.5</radius>
              <length>1</length>
            </cylinder>
          </geometry>
          <max_contacts>10</max_contacts>
          <surface>
            <contact>
              <ode/>
            </contact>
            <bounce/>
            <friction>
              <torsional>
                <ode/>
              </torsional>
              <ode/>
            </friction>
          </surface>
        </collision>
        <visual name='visual'>
          <geometry>
            <cylinder>
              <radius>0.5</radius>
              <length>1</length>
            </cylinder>
          </geometry>
          <material>
            <script>
              <name>Gazebo/Grey</name>
              <uri>file://media/materials/scripts/gazebo.material</uri>
            </script>
          </material>
        </visual>
        <self_collide>0</self_collide>
        <enable_wind>0</enable_wind>
        <kinematic>0</kinematic>
      </link>
    </model>
    <model name='car3'>
      <link name='base_link'>
        <inertial>
          <pose>0.067048 0.007539 0.009259 0 -0 0</pose>
          <mass>16.5899</mass>
          <inertia>
            <ixx>0.350763</ixx>
            <ixy>-0.00589864</ixy>
            <ixz>-0.0572654</ixz>
            <iyy>0.484467</iyy>
            <iyz>-0.0164022</iyz>
            <izz>0.407071</izz>
          </inertia>
        </inertial>
        <collision name='base_link_collision'>
          <pose>0 0 0 0 -0 0</pose>
          <geometry>
            <mesh>
              <scale>1 1 1</scale>
              <uri>/home/xzh/MYHTD/nivigation/myh_ws/src/hunter_se/hunter_se_description/meshes/base_link.STL</uri>
            </mesh>
          </geometry>
          <max_contacts>10</max_contacts>
          <surface>
            <contact>
              <ode/>
            </contact>
            <bounce/>
            <friction>
              <torsional>
                <ode/>
              </torsional>
              <ode/>
            </friction>
          </surface>
        </collision>
        <collision name='base_link_fixed_joint_lump__box_link_collision_1'>
          <pose>0.2 0 0.02 0 -0 0</pose>
          <geometry>
            <mesh>
              <scale>1 1 1</scale>
              <uri>/home/xzh/MYHTD/nivigation/myh_ws/src/hunter_se/hunter_se_description/meshes/box_link.STL</uri>
            </mesh>
          </geometry>
          <max_contacts>10</max_contacts>
          <surface>
            <contact>
              <ode/>
            </contact>
            <bounce/>
            <friction>
              <torsional>
                <ode/>
              </torsional>
              <ode/>
            </friction>
          </surface>
        </collision>
        <collision name='base_link_fixed_joint_lump__laser_livox_collision_2'>
          <pose>0.46 0 0.09 0 -0 0</pose>
          <geometry>
            <box>
              <size>0.01 0.01 0.01</size>
            </box>
          </geometry>
          <surface>
            <contact>
              <ode/>
            </contact>
            <friction>
              <ode/>
              <torsional>
                <ode/>
              </torsional>
            </friction>
            <bounce/>
          </surface>
          <max_contacts>10</max_contacts>
        </collision>
        <visual name='base_link_visual'>
          <pose>0 0 0 0 -0 0</pose>
          <geometry>
            <mesh>
              <scale>1 1 1</scale>
              <uri>/home/xzh/MYHTD/nivigation/myh_ws/src/hunter_se/hunter_se_description/meshes/base_link.STL</uri>
            </mesh>
          </geometry>
        </visual>
        <visual name='base_link_fixed_joint_lump__box_link_visual_1'>
          <pose>0.2 0 0.02 0 -0 0</pose>
          <geometry>
            <mesh>
              <scale>1 1 1</scale>
              <uri>/home/xzh/MYHTD/nivigation/myh_ws/src/hunter_se/hunter_se_description/meshes/box_link.STL</uri>
            </mesh>
          </geometry>
        </visual>
        <visual name='base_link_fixed_joint_lump__laser_livox_visual_2'>
          <pose>0.46 0 0.09 0 -0 0</pose>
          <geometry>
            <box>
              <size>0.01 0.01 0.01</size>
            </box>
          </geometry>
        </visual>
        <sensor name='car3/laser_livox' type='ray'>
          <visualize>1</visualize>
          <update_rate>100</update_rate>
          <plugin name='gazebo_ros_laser_controller' filename='liblivox_laser_simulation.so'>
            <ray>
              <scan>
                <horizontal>
                  <samples>100</samples>
                  <resolution>1</resolution>
                  <min_angle>-0.6143553777777778</min_angle>
                  <max_angle>0.6143553777777778</max_angle>
                </horizontal>
                <vertical>
                  <samples>50</samples>
                  <resolution>1</resolution>
                  <min_angle>-0.6143553777777778</min_angle>
                  <max_angle>0.6143553777777778</max_angle>
                </vertical>
              </scan>
              <range>
                <min>0.1</min>
                <max>200</max>
                <resolution>0.002</resolution>
              </range>
              <noise>
                <type>gaussian</type>
                <mean>0.0</mean>
                <stddev>0.01</stddev>
              </noise>
            </ray>
            <visualize>0</visualize>
            <samples>10000</samples>
            <downsample>1</downsample>
            <csv_file_name>/home/xzh/MYHTD/nivigation/myh_ws/src/livox_laser_simulation/scan_mode/mid70.csv</csv_file_name>
            <ros_topic>car3/scan</ros_topic>
            <robotNamespace>/car3/</robotNamespace>
          </plugin>
          <pose>0.46 0 0.09 0 -0 0</pose>
          <ray>
            <scan>
              <horizontal>
                <samples>640</samples>
                <resolution>1</resolution>
                <min_angle>0</min_angle>
                <max_angle>0</max_angle>
              </horizontal>
              <vertical>
                <samples>1</samples>
                <min_angle>0</min_angle>
                <max_angle>0</max_angle>
              </vertical>
            </scan>
            <range>
              <min>0</min>
              <max>0</max>
            </range>
          </ray>
        </sensor>
        <self_collide>0</self_collide>
        <enable_wind>0</enable_wind>
        <kinematic>0</kinematic>
      </link>
      <joint name='fr_steer_left_joint' type='revolute'>
        <pose relative_to='base_link'>0.34058 0.24619 -0.1535 0 -0 0</pose>
        <parent>base_link</parent>
        <child>fr_steer_left_link</child>
        <axis>
          <xyz>0 0 1</xyz>
          <limit>
            <lower>-0.69</lower>
            <upper>0.69</upper>
            <effort>0</effort>
            <velocity>0</velocity>
          </limit>
          <dynamics>
            <spring_reference>0</spring_reference>
            <spring_stiffness>0</spring_stiffness>
          </dynamics>
        </axis>
      </joint>
      <link name='fr_steer_left_link'>
        <pose relative_to='fr_steer_left_joint'>0 0 0 0 -0 0</pose>
        <inertial>
          <pose>-0.000278 0.016354 0 0 -0 0</pose>
          <mass>1</mass>
          <inertia>
            <ixx>0.0222</ixx>
            <ixy>0</ixy>
            <ixz>0</ixz>
            <iyy>0.0222</iyy>
            <iyz>0</iyz>
            <izz>0.0378075</izz>
          </inertia>
        </inertial>
        <collision name='fr_steer_left_link_collision'>
          <pose>0 0 0 0 -0 0</pose>
          <geometry>
            <box>
              <size>0.001 0.001 0.001</size>
            </box>
          </geometry>
          <max_contacts>10</max_contacts>
          <surface>
            <contact>
              <ode/>
            </contact>
            <bounce/>
            <friction>
              <torsional>
                <ode/>
              </torsional>
              <ode/>
            </friction>
          </surface>
        </collision>
        <visual name='fr_steer_left_link_visual'>
          <pose>0 0 0 0 -0 0</pose>
          <geometry>
            <box>
              <size>0.001 0.001 0.001</size>
            </box>
          </geometry>
        </visual>
        <self_collide>0</self_collide>
        <enable_wind>0</enable_wind>
        <kinematic>0</kinematic>
      </link>
      <joint name='fr_left_joint' type='revolute'>
        <pose relative_to='fr_steer_left_link'>0 0 0 1.5708 -0 0.016976</pose>
        <parent>fr_steer_left_link</parent>
        <child>fr_left_link</child>
        <axis>
          <xyz>0 0 -1</xyz>
          <limit>
            <lower>-1e+16</lower>
            <upper>1e+16</upper>
          </limit>
          <dynamics>
            <spring_reference>0</spring_reference>
            <spring_stiffness>0</spring_stiffness>
          </dynamics>
        </axis>
      </joint>
      <link name='fr_left_link'>
        <pose relative_to='fr_left_joint'>0 0 0 0 -0 0</pose>
        <inertial>
          <pose>-0 0 -0.016356 0 -0 0</pose>
          <mass>1</mass>
          <inertia>
            <ixx>0.0222</ixx>
            <ixy>0</ixy>
            <ixz>0</ixz>
            <iyy>0.0222</iyy>
            <iyz>0</iyz>
            <izz>0.0378075</izz>
          </inertia>
        </inertial>
        <collision name='fr_left_link_collision'>
          <pose>0 0 0 0 -0 0</pose>
          <geometry>
            <mesh>
              <scale>1 1 1</scale>
              <uri>/home/xzh/MYHTD/nivigation/myh_ws/src/hunter_se/hunter_se_description/meshes/fr_left_link.STL</uri>
            </mesh>
          </geometry>
          <max_contacts>10</max_contacts>
          <surface>
            <contact>
              <ode/>
            </contact>
            <bounce/>
            <friction>
              <torsional>
                <ode/>
              </torsional>
              <ode/>
            </friction>
          </surface>
        </collision>
        <visual name='fr_left_link_visual'>
          <pose>0 0 0 0 -0 0</pose>
          <geometry>
            <mesh>
              <scale>1 1 1</scale>
              <uri>/home/xzh/MYHTD/nivigation/myh_ws/src/hunter_se/hunter_se_description/meshes/fr_left_link.STL</uri>
            </mesh>
          </geometry>
        </visual>
        <self_collide>0</self_collide>
        <enable_wind>0</enable_wind>
        <kinematic>0</kinematic>
      </link>
      <joint name='fr_steer_right_joint' type='revolute'>
        <pose relative_to='base_link'>0.34219 -0.24619 -0.1535 0 -0 0</pose>
        <parent>base_link</parent>
        <child>fr_steer_right_link</child>
        <axis>
          <xyz>0 0 1</xyz>
          <limit>
            <lower>-0.69</lower>
            <upper>0.69</upper>
            <effort>0</effort>
            <velocity>0</velocity>
          </limit>
          <dynamics>
            <spring_reference>0</spring_reference>
            <spring_stiffness>0</spring_stiffness>
          </dynamics>
        </axis>
      </joint>
      <link name='fr_steer_right_link'>
        <pose relative_to='fr_steer_right_joint'>0 0 0 0 -0 0</pose>
        <inertial>
          <pose>0.000275 -0.016354 -0 0 -0 0</pose>
          <mass>1</mass>
          <inertia>
            <ixx>0.0222</ixx>
            <ixy>0</ixy>
            <ixz>0</ixz>
            <iyy>0.0222</iyy>
            <iyz>0</iyz>
            <izz>0.0378075</izz>
          </inertia>
        </inertial>
        <collision name='fr_steer_right_link_collision'>
          <pose>0 0 0 0 -0 0</pose>
          <geometry>
            <box>
              <size>0.001 0.001 0.001</size>
            </box>
          </geometry>
          <max_contacts>10</max_contacts>
          <surface>
            <contact>
              <ode/>
            </contact>
            <bounce/>
            <friction>
              <torsional>
                <ode/>
              </torsional>
              <ode/>
            </friction>
          </surface>
        </collision>
        <visual name='fr_steer_right_link_visual'>
          <pose>0 0 0 0 -0 0</pose>
          <geometry>
            <box>
              <size>0.001 0.001 0.001</size>
            </box>
          </geometry>
        </visual>
        <self_collide>0</self_collide>
        <enable_wind>0</enable_wind>
        <kinematic>0</kinematic>
      </link>
      <joint name='fr_right_joint' type='revolute'>
        <pose relative_to='fr_steer_right_link'>0 0 0 -1.5708 0 0</pose>
        <parent>fr_steer_right_link</parent>
        <child>fr_right_link</child>
        <axis>
          <xyz>0 0 1</xyz>
          <limit>
            <lower>-1e+16</lower>
            <upper>1e+16</upper>
          </limit>
          <dynamics>
            <spring_reference>0</spring_reference>
            <spring_stiffness>0</spring_stiffness>
          </dynamics>
        </axis>
      </joint>
      <link name='fr_right_link'>
        <pose relative_to='fr_right_joint'>0 0 0 0 -0 0</pose>
        <inertial>
          <pose>0.000275 0 -0.016354 0 -0 0</pose>
          <mass>1</mass>
          <inertia>
            <ixx>0.0222</ixx>
            <ixy>0</ixy>
            <ixz>0</ixz>
            <iyy>0.0222</iyy>
            <iyz>0</iyz>
            <izz>0.0378075</izz>
          </inertia>
        </inertial>
        <collision name='fr_right_link_collision'>
          <pose>0 0 0 0 -0 0</pose>
          <geometry>
            <mesh>
              <scale>1 1 1</scale>
              <uri>/home/xzh/MYHTD/nivigation/myh_ws/src/hunter_se/hunter_se_description/meshes/fr_right_link.STL</uri>
            </mesh>
          </geometry>
          <max_contacts>10</max_contacts>
          <surface>
            <contact>
              <ode/>
            </contact>
            <bounce/>
            <friction>
              <torsional>
                <ode/>
              </torsional>
              <ode/>
            </friction>
          </surface>
        </collision>
        <visual name='fr_right_link_visual'>
          <pose>0 0 0 0 -0 0</pose>
          <geometry>
            <mesh>
              <scale>1 1 1</scale>
              <uri>/home/xzh/MYHTD/nivigation/myh_ws/src/hunter_se/hunter_se_description/meshes/fr_right_link.STL</uri>
            </mesh>
          </geometry>
        </visual>
        <self_collide>0</self_collide>
        <enable_wind>0</enable_wind>
        <kinematic>0</kinematic>
      </link>
      <joint name='front_steer_joint' type='revolute'>
        <pose relative_to='base_link'>0.40792 -1.1e-05 -0.085581 0 -0 0</pose>
        <parent>base_link</parent>
        <child>front_steer_link</child>
        <axis>
          <xyz>0 0 1</xyz>
          <limit>
            <lower>-0.72</lower>
            <upper>0.72</upper>
            <effort>0</effort>
            <velocity>0</velocity>
          </limit>
          <dynamics>
            <spring_reference>0</spring_reference>
            <spring_stiffness>0</spring_stiffness>
          </dynamics>
        </axis>
      </joint>
      <link name='front_steer_link'>
        <pose relative_to='front_steer_joint'>0 0 0 0 -0 0</pose>
        <inertial>
          <pose>0.049836 0 0.017912 0 -0 0</pose>
          <mass>0.0049179</mass>
          <inertia>
            <ixx>1.6846e-07</ixx>
            <ixy>7.6396e-23</ixy>
            <ixz>-1.0974e-08</ixz>
            <iyy>7.549e-07</iyy>
            <iyz>-1.8957e-22</iyz>
            <izz>7.334e-07</izz>
          </inertia>
        </inertial>
        <collision name='front_steer_link_collision'>
          <pose>0 0 0 0 -0 0</pose>
          <geometry>
            <cylinder>
              <length>0.001</length>
              <radius>0.005</radius>
            </cylinder>
          </geometry>
          <max_contacts>10</max_contacts>
          <surface>
            <contact>
              <ode/>
            </contact>
            <bounce/>
            <friction>
              <torsional>
                <ode/>
              </torsional>
              <ode/>
            </friction>
          </surface>
        </collision>
        <visual name='front_steer_link_visual'>
          <pose>0 0 0 0 -0 0</pose>
          <geometry>
            <cylinder>
              <length>0.001</length>
              <radius>0.005</radius>
            </cylinder>
          </geometry>
        </visual>
        <self_collide>0</self_collide>
        <enable_wind>0</enable_wind>
        <kinematic>0</kinematic>
      </link>
      <joint name='re_left_joint' type='revolute'>
        <pose relative_to='base_link'>-0.2078 0.252 -0.158 1.5708 -0 0</pose>
        <parent>base_link</parent>
        <child>re_left_link</child>
        <axis>
          <xyz>0 0 -1</xyz>
          <limit>
            <lower>-1e+16</lower>
            <upper>1e+16</upper>
          </limit>
          <dynamics>
            <spring_reference>0</spring_reference>
            <spring_stiffness>0</spring_stiffness>
          </dynamics>
        </axis>
      </joint>
      <link name='re_left_link'>
        <pose relative_to='re_left_joint'>0 0 0 0 -0 0</pose>
        <inertial>
          <pose>0 2e-06 -0.010284 0 -0 0</pose>
          <mass>1</mass>
          <inertia>
            <ixx>0.0222</ixx>
            <ixy>0</ixy>
            <ixz>0</ixz>
            <iyy>0.0222</iyy>
            <iyz>0</iyz>
            <izz>0.0378075</izz>
          </inertia>
        </inertial>
        <collision name='re_left_link_collision'>
          <pose>0 0 0 0 -0 0</pose>
          <geometry>
            <mesh>
              <scale>1 1 1</scale>
              <uri>/home/xzh/MYHTD/nivigation/myh_ws/src/hunter_se/hunter_se_description/meshes/re_left_link.STL</uri>
            </mesh>
          </geometry>
          <max_contacts>10</max_contacts>
          <surface>
            <contact>
              <ode/>
            </contact>
            <bounce/>
            <friction>
              <torsional>
                <ode/>
              </torsional>
              <ode/>
            </friction>
          </surface>
        </collision>
        <visual name='re_left_link_visual'>
          <pose>0 0 0 0 -0 0</pose>
          <geometry>
            <mesh>
              <scale>1 1 1</scale>
              <uri>/home/xzh/MYHTD/nivigation/myh_ws/src/hunter_se/hunter_se_description/meshes/re_left_link.STL</uri>
            </mesh>
          </geometry>
        </visual>
        <self_collide>0</self_collide>
        <enable_wind>0</enable_wind>
        <kinematic>0</kinematic>
      </link>
      <joint name='re_right_joint' type='revolute'>
        <pose relative_to='base_link'>-0.2078 -0.252 -0.158 -1.5708 0 0</pose>
        <parent>base_link</parent>
        <child>re_right_link</child>
        <axis>
          <xyz>0 0 1</xyz>
          <limit>
            <lower>-1e+16</lower>
            <upper>1e+16</upper>
          </limit>
          <dynamics>
            <spring_reference>0</spring_reference>
            <spring_stiffness>0</spring_stiffness>
          </dynamics>
        </axis>
      </joint>
      <link name='re_right_link'>
        <pose relative_to='re_right_joint'>0 0 0 0 -0 0</pose>
        <inertial>
          <pose>0 0 0 0 -0 0</pose>
          <mass>1</mass>
          <inertia>
            <ixx>0.0222</ixx>
            <ixy>0</ixy>
            <ixz>0</ixz>
            <iyy>0.0222</iyy>
            <iyz>0</iyz>
            <izz>0.0378075</izz>
          </inertia>
        </inertial>
        <collision name='re_right_link_collision'>
          <pose>0 0 0 0 -0 0</pose>
          <geometry>
            <mesh>
              <scale>1 1 1</scale>
              <uri>/home/xzh/MYHTD/nivigation/myh_ws/src/hunter_se/hunter_se_description/meshes/re_right_link.STL</uri>
            </mesh>
          </geometry>
          <max_contacts>10</max_contacts>
          <surface>
            <contact>
              <ode/>
            </contact>
            <bounce/>
            <friction>
              <torsional>
                <ode/>
              </torsional>
              <ode/>
            </friction>
          </surface>
        </collision>
        <visual name='re_right_link_visual'>
          <pose>0 0 0 0 -0 0</pose>
          <geometry>
            <mesh>
              <scale>1 1 1</scale>
              <uri>/home/xzh/MYHTD/nivigation/myh_ws/src/hunter_se/hunter_se_description/meshes/re_right_link.STL</uri>
            </mesh>
          </geometry>
        </visual>
        <self_collide>0</self_collide>
        <enable_wind>0</enable_wind>
        <kinematic>0</kinematic>
      </link>
      <joint name='rear_wheel_joint' type='revolute'>
        <pose relative_to='base_link'>-0.30408 -1.1e-05 -0.085581 0.003231 -0 0</pose>
        <parent>base_link</parent>
        <child>rear_wheel_link</child>
        <axis>
          <xyz>0 0 1</xyz>
          <limit>
            <lower>-1e+16</lower>
            <upper>1e+16</upper>
          </limit>
          <dynamics>
            <spring_reference>0</spring_reference>
            <spring_stiffness>0</spring_stiffness>
          </dynamics>
        </axis>
      </joint>
      <link name='rear_wheel_link'>
        <pose relative_to='rear_wheel_joint'>0 0 0 0 -0 0</pose>
        <inertial>
          <pose>-0.02 0.003127 -0.12735 0 -0 0</pose>
          <mass>0.0049179</mass>
          <inertia>
            <ixx>1.1821e-06</ixx>
            <ixy>9.6965e-13</ixy>
            <ixz>-3.1553e-12</ixz>
            <iyy>9.5276e-07</iyy>
            <iyz>1.2428e-08</iyz>
            <izz>1.0913e-06</izz>
          </inertia>
        </inertial>
        <collision name='rear_wheel_link_collision'>
          <pose>0 0 0 0 -0 0</pose>
          <geometry>
            <cylinder>
              <length>0.001</length>
              <radius>0.005</radius>
            </cylinder>
          </geometry>
          <max_contacts>10</max_contacts>
          <surface>
            <contact>
              <ode/>
            </contact>
            <bounce/>
            <friction>
              <torsional>
                <ode/>
              </torsional>
              <ode/>
            </friction>
          </surface>
        </collision>
        <visual name='rear_wheel_link_visual'>
          <pose>0 0 0 0 -0 0</pose>
          <geometry>
            <cylinder>
              <length>0.001</length>
              <radius>0.005</radius>
            </cylinder>
          </geometry>
        </visual>
        <self_collide>0</self_collide>
        <enable_wind>0</enable_wind>
        <kinematic>0</kinematic>
      </link>
      <plugin name='gazebo_ros_control' filename='libgazebo_ros_control.so'>
        <robotSimType>steer_bot_hardware_gazebo/SteerBotHardwareGazebo</robotSimType>
        <legacyModeNS>0</legacyModeNS>
        <robotNamespace>/car3/</robotNamespace>
      </plugin>
      <plugin name='imu_controller' filename='libhector_gazebo_ros_imu.so'>
        <robotNamespace>car3</robotNamespace>
        <updateRate>50.0</updateRate>
        <bodyName>base_link</bodyName>
        <frameId>car3/base_link</frameId>
        <topicName>imu/data</topicName>
        <accelDrift>0.005 0.005 0.005</accelDrift>
        <accelGaussianNoise>0.005 0.005 0.005</accelGaussianNoise>
        <rateDrift>0.005 0.005 0.005</rateDrift>
        <rateGaussianNoise>0.005 0.005 0.005</rateGaussianNoise>
        <headingDrift>0.005</headingDrift>
        <headingGaussianNoise>0.005</headingGaussianNoise>
      </plugin>
      <static>0</static>
      <plugin name='gps_controller' filename='libhector_gazebo_ros_gps.so'>
        <robotNamespace>car3</robotNamespace>
        <updateRate>40</updateRate>
        <bodyName>base_link</bodyName>
        <frameId>car3/base_link</frameId>
        <topicName>navsat/fix</topicName>
        <velocityTopicName>navsat/vel</velocityTopicName>
        <referenceLatitude>49.9</referenceLatitude>
        <referenceLongitude>8.9</referenceLongitude>
        <referenceHeading>90</referenceHeading>
        <referenceAltitude>0</referenceAltitude>
        <drift>0.0001 0.0001 0.0001</drift>
      </plugin>
      <pose>8 8 0.36 0 -0 0</pose>
    </model>
    <model name='car1'>
      <link name='base_link'>
        <inertial>
          <pose>0.067048 0.007539 0.009259 0 -0 0</pose>
          <mass>16.5899</mass>
          <inertia>
            <ixx>0.350763</ixx>
            <ixy>-0.00589864</ixy>
            <ixz>-0.0572654</ixz>
            <iyy>0.484467</iyy>
            <iyz>-0.0164022</iyz>
            <izz>0.407071</izz>
          </inertia>
        </inertial>
        <collision name='base_link_collision'>
          <pose>0 0 0 0 -0 0</pose>
          <geometry>
            <mesh>
              <scale>1 1 1</scale>
              <uri>/home/xzh/MYHTD/nivigation/myh_ws/src/hunter_se/hunter_se_description/meshes/base_link.STL</uri>
            </mesh>
          </geometry>
          <max_contacts>10</max_contacts>
          <surface>
            <contact>
              <ode/>
            </contact>
            <bounce/>
            <friction>
              <torsional>
                <ode/>
              </torsional>
              <ode/>
            </friction>
          </surface>
        </collision>
        <collision name='base_link_fixed_joint_lump__box_link_collision_1'>
          <pose>0.2 0 0.02 0 -0 0</pose>
          <geometry>
            <mesh>
              <scale>1 1 1</scale>
              <uri>/home/xzh/MYHTD/nivigation/myh_ws/src/hunter_se/hunter_se_description/meshes/box_link.STL</uri>
            </mesh>
          </geometry>
          <max_contacts>10</max_contacts>
          <surface>
            <contact>
              <ode/>
            </contact>
            <bounce/>
            <friction>
              <torsional>
                <ode/>
              </torsional>
              <ode/>
            </friction>
          </surface>
        </collision>
        <collision name='base_link_fixed_joint_lump__laser_livox_collision_2'>
          <pose>0.46 0 0.09 0 -0 0</pose>
          <geometry>
            <box>
              <size>0.01 0.01 0.01</size>
            </box>
          </geometry>
          <surface>
            <contact>
              <ode/>
            </contact>
            <friction>
              <ode/>
              <torsional>
                <ode/>
              </torsional>
            </friction>
            <bounce/>
          </surface>
          <max_contacts>10</max_contacts>
        </collision>
        <visual name='base_link_visual'>
          <pose>0 0 0 0 -0 0</pose>
          <geometry>
            <mesh>
              <scale>1 1 1</scale>
              <uri>/home/xzh/MYHTD/nivigation/myh_ws/src/hunter_se/hunter_se_description/meshes/base_link.STL</uri>
            </mesh>
          </geometry>
        </visual>
        <visual name='base_link_fixed_joint_lump__box_link_visual_1'>
          <pose>0.2 0 0.02 0 -0 0</pose>
          <geometry>
            <mesh>
              <scale>1 1 1</scale>
              <uri>/home/xzh/MYHTD/nivigation/myh_ws/src/hunter_se/hunter_se_description/meshes/box_link.STL</uri>
            </mesh>
          </geometry>
        </visual>
        <visual name='base_link_fixed_joint_lump__laser_livox_visual_2'>
          <pose>0.46 0 0.09 0 -0 0</pose>
          <geometry>
            <box>
              <size>0.01 0.01 0.01</size>
            </box>
          </geometry>
        </visual>
        <sensor name='car1/laser_livox' type='ray'>
          <visualize>1</visualize>
          <update_rate>100</update_rate>
          <plugin name='gazebo_ros_laser_controller' filename='liblivox_laser_simulation.so'>
            <ray>
              <scan>
                <horizontal>
                  <samples>100</samples>
                  <resolution>1</resolution>
                  <min_angle>-0.6143553777777778</min_angle>
                  <max_angle>0.6143553777777778</max_angle>
                </horizontal>
                <vertical>
                  <samples>50</samples>
                  <resolution>1</resolution>
                  <min_angle>-0.6143553777777778</min_angle>
                  <max_angle>0.6143553777777778</max_angle>
                </vertical>
              </scan>
              <range>
                <min>0.1</min>
                <max>200</max>
                <resolution>0.002</resolution>
              </range>
              <noise>
                <type>gaussian</type>
                <mean>0.0</mean>
                <stddev>0.01</stddev>
              </noise>
            </ray>
            <visualize>0</visualize>
            <samples>10000</samples>
            <downsample>1</downsample>
            <csv_file_name>/home/xzh/MYHTD/nivigation/myh_ws/src/livox_laser_simulation/scan_mode/mid70.csv</csv_file_name>
            <ros_topic>car1/scan</ros_topic>
            <robotNamespace>/car1/</robotNamespace>
          </plugin>
          <pose>0.46 0 0.09 0 -0 0</pose>
          <ray>
            <scan>
              <horizontal>
                <samples>640</samples>
                <resolution>1</resolution>
                <min_angle>0</min_angle>
                <max_angle>0</max_angle>
              </horizontal>
              <vertical>
                <samples>1</samples>
                <min_angle>0</min_angle>
                <max_angle>0</max_angle>
              </vertical>
            </scan>
            <range>
              <min>0</min>
              <max>0</max>
            </range>
          </ray>
        </sensor>
        <self_collide>0</self_collide>
        <enable_wind>0</enable_wind>
        <kinematic>0</kinematic>
      </link>
      <joint name='fr_steer_left_joint' type='revolute'>
        <pose relative_to='base_link'>0.34058 0.24619 -0.1535 0 -0 0</pose>
        <parent>base_link</parent>
        <child>fr_steer_left_link</child>
        <axis>
          <xyz>0 0 1</xyz>
          <limit>
            <lower>-0.69</lower>
            <upper>0.69</upper>
            <effort>0</effort>
            <velocity>0</velocity>
          </limit>
          <dynamics>
            <spring_reference>0</spring_reference>
            <spring_stiffness>0</spring_stiffness>
          </dynamics>
        </axis>
      </joint>
      <link name='fr_steer_left_link'>
        <pose relative_to='fr_steer_left_joint'>0 0 0 0 -0 0</pose>
        <inertial>
          <pose>-0.000278 0.016354 0 0 -0 0</pose>
          <mass>1</mass>
          <inertia>
            <ixx>0.0222</ixx>
            <ixy>0</ixy>
            <ixz>0</ixz>
            <iyy>0.0222</iyy>
            <iyz>0</iyz>
            <izz>0.0378075</izz>
          </inertia>
        </inertial>
        <collision name='fr_steer_left_link_collision'>
          <pose>0 0 0 0 -0 0</pose>
          <geometry>
            <box>
              <size>0.001 0.001 0.001</size>
            </box>
          </geometry>
          <max_contacts>10</max_contacts>
          <surface>
            <contact>
              <ode/>
            </contact>
            <bounce/>
            <friction>
              <torsional>
                <ode/>
              </torsional>
              <ode/>
            </friction>
          </surface>
        </collision>
        <visual name='fr_steer_left_link_visual'>
          <pose>0 0 0 0 -0 0</pose>
          <geometry>
            <box>
              <size>0.001 0.001 0.001</size>
            </box>
          </geometry>
        </visual>
        <self_collide>0</self_collide>
        <enable_wind>0</enable_wind>
        <kinematic>0</kinematic>
      </link>
      <joint name='fr_left_joint' type='revolute'>
        <pose relative_to='fr_steer_left_link'>0 0 0 1.5708 -0 0.016976</pose>
        <parent>fr_steer_left_link</parent>
        <child>fr_left_link</child>
        <axis>
          <xyz>0 0 -1</xyz>
          <limit>
            <lower>-1e+16</lower>
            <upper>1e+16</upper>
          </limit>
          <dynamics>
            <spring_reference>0</spring_reference>
            <spring_stiffness>0</spring_stiffness>
          </dynamics>
        </axis>
      </joint>
      <link name='fr_left_link'>
        <pose relative_to='fr_left_joint'>0 0 0 0 -0 0</pose>
        <inertial>
          <pose>-0 0 -0.016356 0 -0 0</pose>
          <mass>1</mass>
          <inertia>
            <ixx>0.0222</ixx>
            <ixy>0</ixy>
            <ixz>0</ixz>
            <iyy>0.0222</iyy>
            <iyz>0</iyz>
            <izz>0.0378075</izz>
          </inertia>
        </inertial>
        <collision name='fr_left_link_collision'>
          <pose>0 0 0 0 -0 0</pose>
          <geometry>
            <mesh>
              <scale>1 1 1</scale>
              <uri>/home/xzh/MYHTD/nivigation/myh_ws/src/hunter_se/hunter_se_description/meshes/fr_left_link.STL</uri>
            </mesh>
          </geometry>
          <max_contacts>10</max_contacts>
          <surface>
            <contact>
              <ode/>
            </contact>
            <bounce/>
            <friction>
              <torsional>
                <ode/>
              </torsional>
              <ode/>
            </friction>
          </surface>
        </collision>
        <visual name='fr_left_link_visual'>
          <pose>0 0 0 0 -0 0</pose>
          <geometry>
            <mesh>
              <scale>1 1 1</scale>
              <uri>/home/xzh/MYHTD/nivigation/myh_ws/src/hunter_se/hunter_se_description/meshes/fr_left_link.STL</uri>
            </mesh>
          </geometry>
        </visual>
        <self_collide>0</self_collide>
        <enable_wind>0</enable_wind>
        <kinematic>0</kinematic>
      </link>
      <joint name='fr_steer_right_joint' type='revolute'>
        <pose relative_to='base_link'>0.34219 -0.24619 -0.1535 0 -0 0</pose>
        <parent>base_link</parent>
        <child>fr_steer_right_link</child>
        <axis>
          <xyz>0 0 1</xyz>
          <limit>
            <lower>-0.69</lower>
            <upper>0.69</upper>
            <effort>0</effort>
            <velocity>0</velocity>
          </limit>
          <dynamics>
            <spring_reference>0</spring_reference>
            <spring_stiffness>0</spring_stiffness>
          </dynamics>
        </axis>
      </joint>
      <link name='fr_steer_right_link'>
        <pose relative_to='fr_steer_right_joint'>0 0 0 0 -0 0</pose>
        <inertial>
          <pose>0.000275 -0.016354 -0 0 -0 0</pose>
          <mass>1</mass>
          <inertia>
            <ixx>0.0222</ixx>
            <ixy>0</ixy>
            <ixz>0</ixz>
            <iyy>0.0222</iyy>
            <iyz>0</iyz>
            <izz>0.0378075</izz>
          </inertia>
        </inertial>
        <collision name='fr_steer_right_link_collision'>
          <pose>0 0 0 0 -0 0</pose>
          <geometry>
            <box>
              <size>0.001 0.001 0.001</size>
            </box>
          </geometry>
          <max_contacts>10</max_contacts>
          <surface>
            <contact>
              <ode/>
            </contact>
            <bounce/>
            <friction>
              <torsional>
                <ode/>
              </torsional>
              <ode/>
            </friction>
          </surface>
        </collision>
        <visual name='fr_steer_right_link_visual'>
          <pose>0 0 0 0 -0 0</pose>
          <geometry>
            <box>
              <size>0.001 0.001 0.001</size>
            </box>
          </geometry>
        </visual>
        <self_collide>0</self_collide>
        <enable_wind>0</enable_wind>
        <kinematic>0</kinematic>
      </link>
      <joint name='fr_right_joint' type='revolute'>
        <pose relative_to='fr_steer_right_link'>0 0 0 -1.5708 0 0</pose>
        <parent>fr_steer_right_link</parent>
        <child>fr_right_link</child>
        <axis>
          <xyz>0 0 1</xyz>
          <limit>
            <lower>-1e+16</lower>
            <upper>1e+16</upper>
          </limit>
          <dynamics>
            <spring_reference>0</spring_reference>
            <spring_stiffness>0</spring_stiffness>
          </dynamics>
        </axis>
      </joint>
      <link name='fr_right_link'>
        <pose relative_to='fr_right_joint'>0 0 0 0 -0 0</pose>
        <inertial>
          <pose>0.000275 0 -0.016354 0 -0 0</pose>
          <mass>1</mass>
          <inertia>
            <ixx>0.0222</ixx>
            <ixy>0</ixy>
            <ixz>0</ixz>
            <iyy>0.0222</iyy>
            <iyz>0</iyz>
            <izz>0.0378075</izz>
          </inertia>
        </inertial>
        <collision name='fr_right_link_collision'>
          <pose>0 0 0 0 -0 0</pose>
          <geometry>
            <mesh>
              <scale>1 1 1</scale>
              <uri>/home/xzh/MYHTD/nivigation/myh_ws/src/hunter_se/hunter_se_description/meshes/fr_right_link.STL</uri>
            </mesh>
          </geometry>
          <max_contacts>10</max_contacts>
          <surface>
            <contact>
              <ode/>
            </contact>
            <bounce/>
            <friction>
              <torsional>
                <ode/>
              </torsional>
              <ode/>
            </friction>
          </surface>
        </collision>
        <visual name='fr_right_link_visual'>
          <pose>0 0 0 0 -0 0</pose>
          <geometry>
            <mesh>
              <scale>1 1 1</scale>
              <uri>/home/xzh/MYHTD/nivigation/myh_ws/src/hunter_se/hunter_se_description/meshes/fr_right_link.STL</uri>
            </mesh>
          </geometry>
        </visual>
        <self_collide>0</self_collide>
        <enable_wind>0</enable_wind>
        <kinematic>0</kinematic>
      </link>
      <joint name='front_steer_joint' type='revolute'>
        <pose relative_to='base_link'>0.40792 -1.1e-05 -0.085581 0 -0 0</pose>
        <parent>base_link</parent>
        <child>front_steer_link</child>
        <axis>
          <xyz>0 0 1</xyz>
          <limit>
            <lower>-0.72</lower>
            <upper>0.72</upper>
            <effort>0</effort>
            <velocity>0</velocity>
          </limit>
          <dynamics>
            <spring_reference>0</spring_reference>
            <spring_stiffness>0</spring_stiffness>
          </dynamics>
        </axis>
      </joint>
      <link name='front_steer_link'>
        <pose relative_to='front_steer_joint'>0 0 0 0 -0 0</pose>
        <inertial>
          <pose>0.049836 0 0.017912 0 -0 0</pose>
          <mass>0.0049179</mass>
          <inertia>
            <ixx>1.6846e-07</ixx>
            <ixy>7.6396e-23</ixy>
            <ixz>-1.0974e-08</ixz>
            <iyy>7.549e-07</iyy>
            <iyz>-1.8957e-22</iyz>
            <izz>7.334e-07</izz>
          </inertia>
        </inertial>
        <collision name='front_steer_link_collision'>
          <pose>0 0 0 0 -0 0</pose>
          <geometry>
            <cylinder>
              <length>0.001</length>
              <radius>0.005</radius>
            </cylinder>
          </geometry>
          <max_contacts>10</max_contacts>
          <surface>
            <contact>
              <ode/>
            </contact>
            <bounce/>
            <friction>
              <torsional>
                <ode/>
              </torsional>
              <ode/>
            </friction>
          </surface>
        </collision>
        <visual name='front_steer_link_visual'>
          <pose>0 0 0 0 -0 0</pose>
          <geometry>
            <cylinder>
              <length>0.001</length>
              <radius>0.005</radius>
            </cylinder>
          </geometry>
        </visual>
        <self_collide>0</self_collide>
        <enable_wind>0</enable_wind>
        <kinematic>0</kinematic>
      </link>
      <joint name='re_left_joint' type='revolute'>
        <pose relative_to='base_link'>-0.2078 0.252 -0.158 1.5708 -0 0</pose>
        <parent>base_link</parent>
        <child>re_left_link</child>
        <axis>
          <xyz>0 0 -1</xyz>
          <limit>
            <lower>-1e+16</lower>
            <upper>1e+16</upper>
          </limit>
          <dynamics>
            <spring_reference>0</spring_reference>
            <spring_stiffness>0</spring_stiffness>
          </dynamics>
        </axis>
      </joint>
      <link name='re_left_link'>
        <pose relative_to='re_left_joint'>0 0 0 0 -0 0</pose>
        <inertial>
          <pose>0 2e-06 -0.010284 0 -0 0</pose>
          <mass>1</mass>
          <inertia>
            <ixx>0.0222</ixx>
            <ixy>0</ixy>
            <ixz>0</ixz>
            <iyy>0.0222</iyy>
            <iyz>0</iyz>
            <izz>0.0378075</izz>
          </inertia>
        </inertial>
        <collision name='re_left_link_collision'>
          <pose>0 0 0 0 -0 0</pose>
          <geometry>
            <mesh>
              <scale>1 1 1</scale>
              <uri>/home/xzh/MYHTD/nivigation/myh_ws/src/hunter_se/hunter_se_description/meshes/re_left_link.STL</uri>
            </mesh>
          </geometry>
          <max_contacts>10</max_contacts>
          <surface>
            <contact>
              <ode/>
            </contact>
            <bounce/>
            <friction>
              <torsional>
                <ode/>
              </torsional>
              <ode/>
            </friction>
          </surface>
        </collision>
        <visual name='re_left_link_visual'>
          <pose>0 0 0 0 -0 0</pose>
          <geometry>
            <mesh>
              <scale>1 1 1</scale>
              <uri>/home/xzh/MYHTD/nivigation/myh_ws/src/hunter_se/hunter_se_description/meshes/re_left_link.STL</uri>
            </mesh>
          </geometry>
        </visual>
        <self_collide>0</self_collide>
        <enable_wind>0</enable_wind>
        <kinematic>0</kinematic>
      </link>
      <joint name='re_right_joint' type='revolute'>
        <pose relative_to='base_link'>-0.2078 -0.252 -0.158 -1.5708 0 0</pose>
        <parent>base_link</parent>
        <child>re_right_link</child>
        <axis>
          <xyz>0 0 1</xyz>
          <limit>
            <lower>-1e+16</lower>
            <upper>1e+16</upper>
          </limit>
          <dynamics>
            <spring_reference>0</spring_reference>
            <spring_stiffness>0</spring_stiffness>
          </dynamics>
        </axis>
      </joint>
      <link name='re_right_link'>
        <pose relative_to='re_right_joint'>0 0 0 0 -0 0</pose>
        <inertial>
          <pose>0 0 0 0 -0 0</pose>
          <mass>1</mass>
          <inertia>
            <ixx>0.0222</ixx>
            <ixy>0</ixy>
            <ixz>0</ixz>
            <iyy>0.0222</iyy>
            <iyz>0</iyz>
            <izz>0.0378075</izz>
          </inertia>
        </inertial>
        <collision name='re_right_link_collision'>
          <pose>0 0 0 0 -0 0</pose>
          <geometry>
            <mesh>
              <scale>1 1 1</scale>
              <uri>/home/xzh/MYHTD/nivigation/myh_ws/src/hunter_se/hunter_se_description/meshes/re_right_link.STL</uri>
            </mesh>
          </geometry>
          <max_contacts>10</max_contacts>
          <surface>
            <contact>
              <ode/>
            </contact>
            <bounce/>
            <friction>
              <torsional>
                <ode/>
              </torsional>
              <ode/>
            </friction>
          </surface>
        </collision>
        <visual name='re_right_link_visual'>
          <pose>0 0 0 0 -0 0</pose>
          <geometry>
            <mesh>
              <scale>1 1 1</scale>
              <uri>/home/xzh/MYHTD/nivigation/myh_ws/src/hunter_se/hunter_se_description/meshes/re_right_link.STL</uri>
            </mesh>
          </geometry>
        </visual>
        <self_collide>0</self_collide>
        <enable_wind>0</enable_wind>
        <kinematic>0</kinematic>
      </link>
      <joint name='rear_wheel_joint' type='revolute'>
        <pose relative_to='base_link'>-0.30408 -1.1e-05 -0.085581 0.003231 -0 0</pose>
        <parent>base_link</parent>
        <child>rear_wheel_link</child>
        <axis>
          <xyz>0 0 1</xyz>
          <limit>
            <lower>-1e+16</lower>
            <upper>1e+16</upper>
          </limit>
          <dynamics>
            <spring_reference>0</spring_reference>
            <spring_stiffness>0</spring_stiffness>
          </dynamics>
        </axis>
      </joint>
      <link name='rear_wheel_link'>
        <pose relative_to='rear_wheel_joint'>0 0 0 0 -0 0</pose>
        <inertial>
          <pose>-0.02 0.003127 -0.12735 0 -0 0</pose>
          <mass>0.0049179</mass>
          <inertia>
            <ixx>1.1821e-06</ixx>
            <ixy>9.6965e-13</ixy>
            <ixz>-3.1553e-12</ixz>
            <iyy>9.5276e-07</iyy>
            <iyz>1.2428e-08</iyz>
            <izz>1.0913e-06</izz>
          </inertia>
        </inertial>
        <collision name='rear_wheel_link_collision'>
          <pose>0 0 0 0 -0 0</pose>
          <geometry>
            <cylinder>
              <length>0.001</length>
              <radius>0.005</radius>
            </cylinder>
          </geometry>
          <max_contacts>10</max_contacts>
          <surface>
            <contact>
              <ode/>
            </contact>
            <bounce/>
            <friction>
              <torsional>
                <ode/>
              </torsional>
              <ode/>
            </friction>
          </surface>
        </collision>
        <visual name='rear_wheel_link_visual'>
          <pose>0 0 0 0 -0 0</pose>
          <geometry>
            <cylinder>
              <length>0.001</length>
              <radius>0.005</radius>
            </cylinder>
          </geometry>
        </visual>
        <self_collide>0</self_collide>
        <enable_wind>0</enable_wind>
        <kinematic>0</kinematic>
      </link>
      <plugin name='gazebo_ros_control' filename='libgazebo_ros_control.so'>
        <robotSimType>steer_bot_hardware_gazebo/SteerBotHardwareGazebo</robotSimType>
        <legacyModeNS>0</legacyModeNS>
        <robotNamespace>/car1/</robotNamespace>
      </plugin>
      <plugin name='imu_controller' filename='libhector_gazebo_ros_imu.so'>
        <robotNamespace>car1</robotNamespace>
        <updateRate>50.0</updateRate>
        <bodyName>base_link</bodyName>
        <frameId>car1/base_link</frameId>
        <topicName>imu/data</topicName>
        <accelDrift>0.005 0.005 0.005</accelDrift>
        <accelGaussianNoise>0.005 0.005 0.005</accelGaussianNoise>
        <rateDrift>0.005 0.005 0.005</rateDrift>
        <rateGaussianNoise>0.005 0.005 0.005</rateGaussianNoise>
        <headingDrift>0.005</headingDrift>
        <headingGaussianNoise>0.005</headingGaussianNoise>
      </plugin>
      <static>0</static>
      <plugin name='gps_controller' filename='libhector_gazebo_ros_gps.so'>
        <robotNamespace>car1</robotNamespace>
        <updateRate>40</updateRate>
        <bodyName>base_link</bodyName>
        <frameId>car1/base_link</frameId>
        <topicName>navsat/fix</topicName>
        <velocityTopicName>navsat/vel</velocityTopicName>
        <referenceLatitude>49.9</referenceLatitude>
        <referenceLongitude>8.9</referenceLongitude>
        <referenceHeading>90</referenceHeading>
        <referenceAltitude>0</referenceAltitude>
        <drift>0.0001 0.0001 0.0001</drift>
      </plugin>
      <pose>-8 8 0.4 0 -0 0</pose>
    </model>
    <model name='car2'>
      <link name='base_link'>
        <inertial>
          <pose>0.067048 0.007539 0.009259 0 -0 0</pose>
          <mass>16.5899</mass>
          <inertia>
            <ixx>0.350763</ixx>
            <ixy>-0.00589864</ixy>
            <ixz>-0.0572654</ixz>
            <iyy>0.484467</iyy>
            <iyz>-0.0164022</iyz>
            <izz>0.407071</izz>
          </inertia>
        </inertial>
        <collision name='base_link_collision'>
          <pose>0 0 0 0 -0 0</pose>
          <geometry>
            <mesh>
              <scale>1 1 1</scale>
              <uri>/home/xzh/MYHTD/nivigation/myh_ws/src/hunter_se/hunter_se_description/meshes/base_link.STL</uri>
            </mesh>
          </geometry>
          <max_contacts>10</max_contacts>
          <surface>
            <contact>
              <ode/>
            </contact>
            <bounce/>
            <friction>
              <torsional>
                <ode/>
              </torsional>
              <ode/>
            </friction>
          </surface>
        </collision>
        <collision name='base_link_fixed_joint_lump__box_link_collision_1'>
          <pose>0.2 0 0.02 0 -0 0</pose>
          <geometry>
            <mesh>
              <scale>1 1 1</scale>
              <uri>/home/xzh/MYHTD/nivigation/myh_ws/src/hunter_se/hunter_se_description/meshes/box_link.STL</uri>
            </mesh>
          </geometry>
          <max_contacts>10</max_contacts>
          <surface>
            <contact>
              <ode/>
            </contact>
            <bounce/>
            <friction>
              <torsional>
                <ode/>
              </torsional>
              <ode/>
            </friction>
          </surface>
        </collision>
        <collision name='base_link_fixed_joint_lump__laser_livox_collision_2'>
          <pose>0.46 0 0.09 0 -0 0</pose>
          <geometry>
            <box>
              <size>0.01 0.01 0.01</size>
            </box>
          </geometry>
          <surface>
            <contact>
              <ode/>
            </contact>
            <friction>
              <ode/>
              <torsional>
                <ode/>
              </torsional>
            </friction>
            <bounce/>
          </surface>
          <max_contacts>10</max_contacts>
        </collision>
        <visual name='base_link_visual'>
          <pose>0 0 0 0 -0 0</pose>
          <geometry>
            <mesh>
              <scale>1 1 1</scale>
              <uri>/home/xzh/MYHTD/nivigation/myh_ws/src/hunter_se/hunter_se_description/meshes/base_link.STL</uri>
            </mesh>
          </geometry>
        </visual>
        <visual name='base_link_fixed_joint_lump__box_link_visual_1'>
          <pose>0.2 0 0.02 0 -0 0</pose>
          <geometry>
            <mesh>
              <scale>1 1 1</scale>
              <uri>/home/xzh/MYHTD/nivigation/myh_ws/src/hunter_se/hunter_se_description/meshes/box_link.STL</uri>
            </mesh>
          </geometry>
        </visual>
        <visual name='base_link_fixed_joint_lump__laser_livox_visual_2'>
          <pose>0.46 0 0.09 0 -0 0</pose>
          <geometry>
            <box>
              <size>0.01 0.01 0.01</size>
            </box>
          </geometry>
        </visual>
        <sensor name='car2/laser_livox' type='ray'>
          <visualize>1</visualize>
          <update_rate>100</update_rate>
          <plugin name='gazebo_ros_laser_controller' filename='liblivox_laser_simulation.so'>
            <ray>
              <scan>
                <horizontal>
                  <samples>100</samples>
                  <resolution>1</resolution>
                  <min_angle>-0.6143553777777778</min_angle>
                  <max_angle>0.6143553777777778</max_angle>
                </horizontal>
                <vertical>
                  <samples>50</samples>
                  <resolution>1</resolution>
                  <min_angle>-0.6143553777777778</min_angle>
                  <max_angle>0.6143553777777778</max_angle>
                </vertical>
              </scan>
              <range>
                <min>0.1</min>
                <max>200</max>
                <resolution>0.002</resolution>
              </range>
              <noise>
                <type>gaussian</type>
                <mean>0.0</mean>
                <stddev>0.01</stddev>
              </noise>
            </ray>
            <visualize>0</visualize>
            <samples>10000</samples>
            <downsample>1</downsample>
            <csv_file_name>/home/xzh/MYHTD/nivigation/myh_ws/src/livox_laser_simulation/scan_mode/mid70.csv</csv_file_name>
            <ros_topic>car2/scan</ros_topic>
            <robotNamespace>/car2/</robotNamespace>
          </plugin>
          <pose>0.46 0 0.09 0 -0 0</pose>
          <ray>
            <scan>
              <horizontal>
                <samples>640</samples>
                <resolution>1</resolution>
                <min_angle>0</min_angle>
                <max_angle>0</max_angle>
              </horizontal>
              <vertical>
                <samples>1</samples>
                <min_angle>0</min_angle>
                <max_angle>0</max_angle>
              </vertical>
            </scan>
            <range>
              <min>0</min>
              <max>0</max>
            </range>
          </ray>
        </sensor>
        <self_collide>0</self_collide>
        <enable_wind>0</enable_wind>
        <kinematic>0</kinematic>
      </link>
      <joint name='fr_steer_left_joint' type='revolute'>
        <pose relative_to='base_link'>0.34058 0.24619 -0.1535 0 -0 0</pose>
        <parent>base_link</parent>
        <child>fr_steer_left_link</child>
        <axis>
          <xyz>0 0 1</xyz>
          <limit>
            <lower>-0.69</lower>
            <upper>0.69</upper>
            <effort>0</effort>
            <velocity>0</velocity>
          </limit>
          <dynamics>
            <spring_reference>0</spring_reference>
            <spring_stiffness>0</spring_stiffness>
          </dynamics>
        </axis>
      </joint>
      <link name='fr_steer_left_link'>
        <pose relative_to='fr_steer_left_joint'>0 0 0 0 -0 0</pose>
        <inertial>
          <pose>-0.000278 0.016354 0 0 -0 0</pose>
          <mass>1</mass>
          <inertia>
            <ixx>0.0222</ixx>
            <ixy>0</ixy>
            <ixz>0</ixz>
            <iyy>0.0222</iyy>
            <iyz>0</iyz>
            <izz>0.0378075</izz>
          </inertia>
        </inertial>
        <collision name='fr_steer_left_link_collision'>
          <pose>0 0 0 0 -0 0</pose>
          <geometry>
            <box>
              <size>0.001 0.001 0.001</size>
            </box>
          </geometry>
          <max_contacts>10</max_contacts>
          <surface>
            <contact>
              <ode/>
            </contact>
            <bounce/>
            <friction>
              <torsional>
                <ode/>
              </torsional>
              <ode/>
            </friction>
          </surface>
        </collision>
        <visual name='fr_steer_left_link_visual'>
          <pose>0 0 0 0 -0 0</pose>
          <geometry>
            <box>
              <size>0.001 0.001 0.001</size>
            </box>
          </geometry>
        </visual>
        <self_collide>0</self_collide>
        <enable_wind>0</enable_wind>
        <kinematic>0</kinematic>
      </link>
      <joint name='fr_left_joint' type='revolute'>
        <pose relative_to='fr_steer_left_link'>0 0 0 1.5708 -0 0.016976</pose>
        <parent>fr_steer_left_link</parent>
        <child>fr_left_link</child>
        <axis>
          <xyz>0 0 -1</xyz>
          <limit>
            <lower>-1e+16</lower>
            <upper>1e+16</upper>
          </limit>
          <dynamics>
            <spring_reference>0</spring_reference>
            <spring_stiffness>0</spring_stiffness>
          </dynamics>
        </axis>
      </joint>
      <link name='fr_left_link'>
        <pose relative_to='fr_left_joint'>0 0 0 0 -0 0</pose>
        <inertial>
          <pose>-0 0 -0.016356 0 -0 0</pose>
          <mass>1</mass>
          <inertia>
            <ixx>0.0222</ixx>
            <ixy>0</ixy>
            <ixz>0</ixz>
            <iyy>0.0222</iyy>
            <iyz>0</iyz>
            <izz>0.0378075</izz>
          </inertia>
        </inertial>
        <collision name='fr_left_link_collision'>
          <pose>0 0 0 0 -0 0</pose>
          <geometry>
            <mesh>
              <scale>1 1 1</scale>
              <uri>/home/xzh/MYHTD/nivigation/myh_ws/src/hunter_se/hunter_se_description/meshes/fr_left_link.STL</uri>
            </mesh>
          </geometry>
          <max_contacts>10</max_contacts>
          <surface>
            <contact>
              <ode/>
            </contact>
            <bounce/>
            <friction>
              <torsional>
                <ode/>
              </torsional>
              <ode/>
            </friction>
          </surface>
        </collision>
        <visual name='fr_left_link_visual'>
          <pose>0 0 0 0 -0 0</pose>
          <geometry>
            <mesh>
              <scale>1 1 1</scale>
              <uri>/home/xzh/MYHTD/nivigation/myh_ws/src/hunter_se/hunter_se_description/meshes/fr_left_link.STL</uri>
            </mesh>
          </geometry>
        </visual>
        <self_collide>0</self_collide>
        <enable_wind>0</enable_wind>
        <kinematic>0</kinematic>
      </link>
      <joint name='fr_steer_right_joint' type='revolute'>
        <pose relative_to='base_link'>0.34219 -0.24619 -0.1535 0 -0 0</pose>
        <parent>base_link</parent>
        <child>fr_steer_right_link</child>
        <axis>
          <xyz>0 0 1</xyz>
          <limit>
            <lower>-0.69</lower>
            <upper>0.69</upper>
            <effort>0</effort>
            <velocity>0</velocity>
          </limit>
          <dynamics>
            <spring_reference>0</spring_reference>
            <spring_stiffness>0</spring_stiffness>
          </dynamics>
        </axis>
      </joint>
      <link name='fr_steer_right_link'>
        <pose relative_to='fr_steer_right_joint'>0 0 0 0 -0 0</pose>
        <inertial>
          <pose>0.000275 -0.016354 -0 0 -0 0</pose>
          <mass>1</mass>
          <inertia>
            <ixx>0.0222</ixx>
            <ixy>0</ixy>
            <ixz>0</ixz>
            <iyy>0.0222</iyy>
            <iyz>0</iyz>
            <izz>0.0378075</izz>
          </inertia>
        </inertial>
        <collision name='fr_steer_right_link_collision'>
          <pose>0 0 0 0 -0 0</pose>
          <geometry>
            <box>
              <size>0.001 0.001 0.001</size>
            </box>
          </geometry>
          <max_contacts>10</max_contacts>
          <surface>
            <contact>
              <ode/>
            </contact>
            <bounce/>
            <friction>
              <torsional>
                <ode/>
              </torsional>
              <ode/>
            </friction>
          </surface>
        </collision>
        <visual name='fr_steer_right_link_visual'>
          <pose>0 0 0 0 -0 0</pose>
          <geometry>
            <box>
              <size>0.001 0.001 0.001</size>
            </box>
          </geometry>
        </visual>
        <self_collide>0</self_collide>
        <enable_wind>0</enable_wind>
        <kinematic>0</kinematic>
      </link>
      <joint name='fr_right_joint' type='revolute'>
        <pose relative_to='fr_steer_right_link'>0 0 0 -1.5708 0 0</pose>
        <parent>fr_steer_right_link</parent>
        <child>fr_right_link</child>
        <axis>
          <xyz>0 0 1</xyz>
          <limit>
            <lower>-1e+16</lower>
            <upper>1e+16</upper>
          </limit>
          <dynamics>
            <spring_reference>0</spring_reference>
            <spring_stiffness>0</spring_stiffness>
          </dynamics>
        </axis>
      </joint>
      <link name='fr_right_link'>
        <pose relative_to='fr_right_joint'>0 0 0 0 -0 0</pose>
        <inertial>
          <pose>0.000275 0 -0.016354 0 -0 0</pose>
          <mass>1</mass>
          <inertia>
            <ixx>0.0222</ixx>
            <ixy>0</ixy>
            <ixz>0</ixz>
            <iyy>0.0222</iyy>
            <iyz>0</iyz>
            <izz>0.0378075</izz>
          </inertia>
        </inertial>
        <collision name='fr_right_link_collision'>
          <pose>0 0 0 0 -0 0</pose>
          <geometry>
            <mesh>
              <scale>1 1 1</scale>
              <uri>/home/xzh/MYHTD/nivigation/myh_ws/src/hunter_se/hunter_se_description/meshes/fr_right_link.STL</uri>
            </mesh>
          </geometry>
          <max_contacts>10</max_contacts>
          <surface>
            <contact>
              <ode/>
            </contact>
            <bounce/>
            <friction>
              <torsional>
                <ode/>
              </torsional>
              <ode/>
            </friction>
          </surface>
        </collision>
        <visual name='fr_right_link_visual'>
          <pose>0 0 0 0 -0 0</pose>
          <geometry>
            <mesh>
              <scale>1 1 1</scale>
              <uri>/home/xzh/MYHTD/nivigation/myh_ws/src/hunter_se/hunter_se_description/meshes/fr_right_link.STL</uri>
            </mesh>
          </geometry>
        </visual>
        <self_collide>0</self_collide>
        <enable_wind>0</enable_wind>
        <kinematic>0</kinematic>
      </link>
      <joint name='front_steer_joint' type='revolute'>
        <pose relative_to='base_link'>0.40792 -1.1e-05 -0.085581 0 -0 0</pose>
        <parent>base_link</parent>
        <child>front_steer_link</child>
        <axis>
          <xyz>0 0 1</xyz>
          <limit>
            <lower>-0.72</lower>
            <upper>0.72</upper>
            <effort>0</effort>
            <velocity>0</velocity>
          </limit>
          <dynamics>
            <spring_reference>0</spring_reference>
            <spring_stiffness>0</spring_stiffness>
          </dynamics>
        </axis>
      </joint>
      <link name='front_steer_link'>
        <pose relative_to='front_steer_joint'>0 0 0 0 -0 0</pose>
        <inertial>
          <pose>0.049836 0 0.017912 0 -0 0</pose>
          <mass>0.0049179</mass>
          <inertia>
            <ixx>1.6846e-07</ixx>
            <ixy>7.6396e-23</ixy>
            <ixz>-1.0974e-08</ixz>
            <iyy>7.549e-07</iyy>
            <iyz>-1.8957e-22</iyz>
            <izz>7.334e-07</izz>
          </inertia>
        </inertial>
        <collision name='front_steer_link_collision'>
          <pose>0 0 0 0 -0 0</pose>
          <geometry>
            <cylinder>
              <length>0.001</length>
              <radius>0.005</radius>
            </cylinder>
          </geometry>
          <max_contacts>10</max_contacts>
          <surface>
            <contact>
              <ode/>
            </contact>
            <bounce/>
            <friction>
              <torsional>
                <ode/>
              </torsional>
              <ode/>
            </friction>
          </surface>
        </collision>
        <visual name='front_steer_link_visual'>
          <pose>0 0 0 0 -0 0</pose>
          <geometry>
            <cylinder>
              <length>0.001</length>
              <radius>0.005</radius>
            </cylinder>
          </geometry>
        </visual>
        <self_collide>0</self_collide>
        <enable_wind>0</enable_wind>
        <kinematic>0</kinematic>
      </link>
      <joint name='re_left_joint' type='revolute'>
        <pose relative_to='base_link'>-0.2078 0.252 -0.158 1.5708 -0 0</pose>
        <parent>base_link</parent>
        <child>re_left_link</child>
        <axis>
          <xyz>0 0 -1</xyz>
          <limit>
            <lower>-1e+16</lower>
            <upper>1e+16</upper>
          </limit>
          <dynamics>
            <spring_reference>0</spring_reference>
            <spring_stiffness>0</spring_stiffness>
          </dynamics>
        </axis>
      </joint>
      <link name='re_left_link'>
        <pose relative_to='re_left_joint'>0 0 0 0 -0 0</pose>
        <inertial>
          <pose>0 2e-06 -0.010284 0 -0 0</pose>
          <mass>1</mass>
          <inertia>
            <ixx>0.0222</ixx>
            <ixy>0</ixy>
            <ixz>0</ixz>
            <iyy>0.0222</iyy>
            <iyz>0</iyz>
            <izz>0.0378075</izz>
          </inertia>
        </inertial>
        <collision name='re_left_link_collision'>
          <pose>0 0 0 0 -0 0</pose>
          <geometry>
            <mesh>
              <scale>1 1 1</scale>
              <uri>/home/xzh/MYHTD/nivigation/myh_ws/src/hunter_se/hunter_se_description/meshes/re_left_link.STL</uri>
            </mesh>
          </geometry>
          <max_contacts>10</max_contacts>
          <surface>
            <contact>
              <ode/>
            </contact>
            <bounce/>
            <friction>
              <torsional>
                <ode/>
              </torsional>
              <ode/>
            </friction>
          </surface>
        </collision>
        <visual name='re_left_link_visual'>
          <pose>0 0 0 0 -0 0</pose>
          <geometry>
            <mesh>
              <scale>1 1 1</scale>
              <uri>/home/xzh/MYHTD/nivigation/myh_ws/src/hunter_se/hunter_se_description/meshes/re_left_link.STL</uri>
            </mesh>
          </geometry>
        </visual>
        <self_collide>0</self_collide>
        <enable_wind>0</enable_wind>
        <kinematic>0</kinematic>
      </link>
      <joint name='re_right_joint' type='revolute'>
        <pose relative_to='base_link'>-0.2078 -0.252 -0.158 -1.5708 0 0</pose>
        <parent>base_link</parent>
        <child>re_right_link</child>
        <axis>
          <xyz>0 0 1</xyz>
          <limit>
            <lower>-1e+16</lower>
            <upper>1e+16</upper>
          </limit>
          <dynamics>
            <spring_reference>0</spring_reference>
            <spring_stiffness>0</spring_stiffness>
          </dynamics>
        </axis>
      </joint>
      <link name='re_right_link'>
        <pose relative_to='re_right_joint'>0 0 0 0 -0 0</pose>
        <inertial>
          <pose>0 0 0 0 -0 0</pose>
          <mass>1</mass>
          <inertia>
            <ixx>0.0222</ixx>
            <ixy>0</ixy>
            <ixz>0</ixz>
            <iyy>0.0222</iyy>
            <iyz>0</iyz>
            <izz>0.0378075</izz>
          </inertia>
        </inertial>
        <collision name='re_right_link_collision'>
          <pose>0 0 0 0 -0 0</pose>
          <geometry>
            <mesh>
              <scale>1 1 1</scale>
              <uri>/home/xzh/MYHTD/nivigation/myh_ws/src/hunter_se/hunter_se_description/meshes/re_right_link.STL</uri>
            </mesh>
          </geometry>
          <max_contacts>10</max_contacts>
          <surface>
            <contact>
              <ode/>
            </contact>
            <bounce/>
            <friction>
              <torsional>
                <ode/>
              </torsional>
              <ode/>
            </friction>
          </surface>
        </collision>
        <visual name='re_right_link_visual'>
          <pose>0 0 0 0 -0 0</pose>
          <geometry>
            <mesh>
              <scale>1 1 1</scale>
              <uri>/home/xzh/MYHTD/nivigation/myh_ws/src/hunter_se/hunter_se_description/meshes/re_right_link.STL</uri>
            </mesh>
          </geometry>
        </visual>
        <self_collide>0</self_collide>
        <enable_wind>0</enable_wind>
        <kinematic>0</kinematic>
      </link>
      <joint name='rear_wheel_joint' type='revolute'>
        <pose relative_to='base_link'>-0.30408 -1.1e-05 -0.085581 0.003231 -0 0</pose>
        <parent>base_link</parent>
        <child>rear_wheel_link</child>
        <axis>
          <xyz>0 0 1</xyz>
          <limit>
            <lower>-1e+16</lower>
            <upper>1e+16</upper>
          </limit>
          <dynamics>
            <spring_reference>0</spring_reference>
            <spring_stiffness>0</spring_stiffness>
          </dynamics>
        </axis>
      </joint>
      <link name='rear_wheel_link'>
        <pose relative_to='rear_wheel_joint'>0 0 0 0 -0 0</pose>
        <inertial>
          <pose>-0.02 0.003127 -0.12735 0 -0 0</pose>
          <mass>0.0049179</mass>
          <inertia>
            <ixx>1.1821e-06</ixx>
            <ixy>9.6965e-13</ixy>
            <ixz>-3.1553e-12</ixz>
            <iyy>9.5276e-07</iyy>
            <iyz>1.2428e-08</iyz>
            <izz>1.0913e-06</izz>
          </inertia>
        </inertial>
        <collision name='rear_wheel_link_collision'>
          <pose>0 0 0 0 -0 0</pose>
          <geometry>
            <cylinder>
              <length>0.001</length>
              <radius>0.005</radius>
            </cylinder>
          </geometry>
          <max_contacts>10</max_contacts>
          <surface>
            <contact>
              <ode/>
            </contact>
            <bounce/>
            <friction>
              <torsional>
                <ode/>
              </torsional>
              <ode/>
            </friction>
          </surface>
        </collision>
        <visual name='rear_wheel_link_visual'>
          <pose>0 0 0 0 -0 0</pose>
          <geometry>
            <cylinder>
              <length>0.001</length>
              <radius>0.005</radius>
            </cylinder>
          </geometry>
        </visual>
        <self_collide>0</self_collide>
        <enable_wind>0</enable_wind>
        <kinematic>0</kinematic>
      </link>
      <plugin name='gazebo_ros_control' filename='libgazebo_ros_control.so'>
        <robotSimType>steer_bot_hardware_gazebo/SteerBotHardwareGazebo</robotSimType>
        <legacyModeNS>0</legacyModeNS>
        <robotNamespace>/car2/</robotNamespace>
      </plugin>
      <plugin name='imu_controller' filename='libhector_gazebo_ros_imu.so'>
        <robotNamespace>car2</robotNamespace>
        <updateRate>50.0</updateRate>
        <bodyName>base_link</bodyName>
        <frameId>car2/base_link</frameId>
        <topicName>imu/data</topicName>
        <accelDrift>0.005 0.005 0.005</accelDrift>
        <accelGaussianNoise>0.005 0.005 0.005</accelGaussianNoise>
        <rateDrift>0.005 0.005 0.005</rateDrift>
        <rateGaussianNoise>0.005 0.005 0.005</rateGaussianNoise>
        <headingDrift>0.005</headingDrift>
        <headingGaussianNoise>0.005</headingGaussianNoise>
      </plugin>
      <static>0</static>
      <plugin name='gps_controller' filename='libhector_gazebo_ros_gps.so'>
        <robotNamespace>car2</robotNamespace>
        <updateRate>40</updateRate>
        <bodyName>base_link</bodyName>
        <frameId>car2/base_link</frameId>
        <topicName>navsat/fix</topicName>
        <velocityTopicName>navsat/vel</velocityTopicName>
        <referenceLatitude>49.9</referenceLatitude>
        <referenceLongitude>8.9</referenceLongitude>
        <referenceHeading>90</referenceHeading>
        <referenceAltitude>0</referenceAltitude>
        <drift>0.0001 0.0001 0.0001</drift>
      </plugin>
      <pose>-8 -8 0.4 0 -0 0</pose>
    </model>
    <model name='car4'>
      <link name='base_link'>
        <inertial>
          <pose>0.067048 0.007539 0.009259 0 -0 0</pose>
          <mass>16.5899</mass>
          <inertia>
            <ixx>0.350763</ixx>
            <ixy>-0.00589864</ixy>
            <ixz>-0.0572654</ixz>
            <iyy>0.484467</iyy>
            <iyz>-0.0164022</iyz>
            <izz>0.407071</izz>
          </inertia>
        </inertial>
        <collision name='base_link_collision'>
          <pose>0 0 0 0 -0 0</pose>
          <geometry>
            <mesh>
              <scale>1 1 1</scale>
              <uri>/home/xzh/MYHTD/nivigation/myh_ws/src/hunter_se/hunter_se_description/meshes/base_link.STL</uri>
            </mesh>
          </geometry>
          <max_contacts>10</max_contacts>
          <surface>
            <contact>
              <ode/>
            </contact>
            <bounce/>
            <friction>
              <torsional>
                <ode/>
              </torsional>
              <ode/>
            </friction>
          </surface>
        </collision>
        <collision name='base_link_fixed_joint_lump__box_link_collision_1'>
          <pose>0.2 0 0.02 0 -0 0</pose>
          <geometry>
            <mesh>
              <scale>1 1 1</scale>
              <uri>/home/xzh/MYHTD/nivigation/myh_ws/src/hunter_se/hunter_se_description/meshes/box_link.STL</uri>
            </mesh>
          </geometry>
          <max_contacts>10</max_contacts>
          <surface>
            <contact>
              <ode/>
            </contact>
            <bounce/>
            <friction>
              <torsional>
                <ode/>
              </torsional>
              <ode/>
            </friction>
          </surface>
        </collision>
        <collision name='base_link_fixed_joint_lump__laser_livox_collision_2'>
          <pose>0.46 0 0.09 0 -0 0</pose>
          <geometry>
            <box>
              <size>0.01 0.01 0.01</size>
            </box>
          </geometry>
          <surface>
            <contact>
              <ode/>
            </contact>
            <friction>
              <ode/>
              <torsional>
                <ode/>
              </torsional>
            </friction>
            <bounce/>
          </surface>
          <max_contacts>10</max_contacts>
        </collision>
        <visual name='base_link_visual'>
          <pose>0 0 0 0 -0 0</pose>
          <geometry>
            <mesh>
              <scale>1 1 1</scale>
              <uri>/home/xzh/MYHTD/nivigation/myh_ws/src/hunter_se/hunter_se_description/meshes/base_link.STL</uri>
            </mesh>
          </geometry>
        </visual>
        <visual name='base_link_fixed_joint_lump__box_link_visual_1'>
          <pose>0.2 0 0.02 0 -0 0</pose>
          <geometry>
            <mesh>
              <scale>1 1 1</scale>
              <uri>/home/xzh/MYHTD/nivigation/myh_ws/src/hunter_se/hunter_se_description/meshes/box_link.STL</uri>
            </mesh>
          </geometry>
        </visual>
        <visual name='base_link_fixed_joint_lump__laser_livox_visual_2'>
          <pose>0.46 0 0.09 0 -0 0</pose>
          <geometry>
            <box>
              <size>0.01 0.01 0.01</size>
            </box>
          </geometry>
        </visual>
        <sensor name='car4/laser_livox' type='ray'>
          <visualize>1</visualize>
          <update_rate>100</update_rate>
          <plugin name='gazebo_ros_laser_controller' filename='liblivox_laser_simulation.so'>
            <ray>
              <scan>
                <horizontal>
                  <samples>100</samples>
                  <resolution>1</resolution>
                  <min_angle>-0.6143553777777778</min_angle>
                  <max_angle>0.6143553777777778</max_angle>
                </horizontal>
                <vertical>
                  <samples>50</samples>
                  <resolution>1</resolution>
                  <min_angle>-0.6143553777777778</min_angle>
                  <max_angle>0.6143553777777778</max_angle>
                </vertical>
              </scan>
              <range>
                <min>0.1</min>
                <max>200</max>
                <resolution>0.002</resolution>
              </range>
              <noise>
                <type>gaussian</type>
                <mean>0.0</mean>
                <stddev>0.01</stddev>
              </noise>
            </ray>
            <visualize>0</visualize>
            <samples>10000</samples>
            <downsample>1</downsample>
            <csv_file_name>/home/xzh/MYHTD/nivigation/myh_ws/src/livox_laser_simulation/scan_mode/mid70.csv</csv_file_name>
            <ros_topic>car4/scan</ros_topic>
            <robotNamespace>/car4/</robotNamespace>
          </plugin>
          <pose>0.46 0 0.09 0 -0 0</pose>
          <ray>
            <scan>
              <horizontal>
                <samples>640</samples>
                <resolution>1</resolution>
                <min_angle>0</min_angle>
                <max_angle>0</max_angle>
              </horizontal>
              <vertical>
                <samples>1</samples>
                <min_angle>0</min_angle>
                <max_angle>0</max_angle>
              </vertical>
            </scan>
            <range>
              <min>0</min>
              <max>0</max>
            </range>
          </ray>
        </sensor>
        <self_collide>0</self_collide>
        <enable_wind>0</enable_wind>
        <kinematic>0</kinematic>
      </link>
      <joint name='fr_steer_left_joint' type='revolute'>
        <pose relative_to='base_link'>0.34058 0.24619 -0.1535 0 -0 0</pose>
        <parent>base_link</parent>
        <child>fr_steer_left_link</child>
        <axis>
          <xyz>0 0 1</xyz>
          <limit>
            <lower>-0.69</lower>
            <upper>0.69</upper>
            <effort>0</effort>
            <velocity>0</velocity>
          </limit>
          <dynamics>
            <spring_reference>0</spring_reference>
            <spring_stiffness>0</spring_stiffness>
          </dynamics>
        </axis>
      </joint>
      <link name='fr_steer_left_link'>
        <pose relative_to='fr_steer_left_joint'>0 0 0 0 -0 0</pose>
        <inertial>
          <pose>-0.000278 0.016354 0 0 -0 0</pose>
          <mass>1</mass>
          <inertia>
            <ixx>0.0222</ixx>
            <ixy>0</ixy>
            <ixz>0</ixz>
            <iyy>0.0222</iyy>
            <iyz>0</iyz>
            <izz>0.0378075</izz>
          </inertia>
        </inertial>
        <collision name='fr_steer_left_link_collision'>
          <pose>0 0 0 0 -0 0</pose>
          <geometry>
            <box>
              <size>0.001 0.001 0.001</size>
            </box>
          </geometry>
          <max_contacts>10</max_contacts>
          <surface>
            <contact>
              <ode/>
            </contact>
            <bounce/>
            <friction>
              <torsional>
                <ode/>
              </torsional>
              <ode/>
            </friction>
          </surface>
        </collision>
        <visual name='fr_steer_left_link_visual'>
          <pose>0 0 0 0 -0 0</pose>
          <geometry>
            <box>
              <size>0.001 0.001 0.001</size>
            </box>
          </geometry>
        </visual>
        <self_collide>0</self_collide>
        <enable_wind>0</enable_wind>
        <kinematic>0</kinematic>
      </link>
      <joint name='fr_left_joint' type='revolute'>
        <pose relative_to='fr_steer_left_link'>0 0 0 1.5708 -0 0.016976</pose>
        <parent>fr_steer_left_link</parent>
        <child>fr_left_link</child>
        <axis>
          <xyz>0 0 -1</xyz>
          <limit>
            <lower>-1e+16</lower>
            <upper>1e+16</upper>
          </limit>
          <dynamics>
            <spring_reference>0</spring_reference>
            <spring_stiffness>0</spring_stiffness>
          </dynamics>
        </axis>
      </joint>
      <link name='fr_left_link'>
        <pose relative_to='fr_left_joint'>0 0 0 0 -0 0</pose>
        <inertial>
          <pose>-0 0 -0.016356 0 -0 0</pose>
          <mass>1</mass>
          <inertia>
            <ixx>0.0222</ixx>
            <ixy>0</ixy>
            <ixz>0</ixz>
            <iyy>0.0222</iyy>
            <iyz>0</iyz>
            <izz>0.0378075</izz>
          </inertia>
        </inertial>
        <collision name='fr_left_link_collision'>
          <pose>0 0 0 0 -0 0</pose>
          <geometry>
            <mesh>
              <scale>1 1 1</scale>
              <uri>/home/xzh/MYHTD/nivigation/myh_ws/src/hunter_se/hunter_se_description/meshes/fr_left_link.STL</uri>
            </mesh>
          </geometry>
          <max_contacts>10</max_contacts>
          <surface>
            <contact>
              <ode/>
            </contact>
            <bounce/>
            <friction>
              <torsional>
                <ode/>
              </torsional>
              <ode/>
            </friction>
          </surface>
        </collision>
        <visual name='fr_left_link_visual'>
          <pose>0 0 0 0 -0 0</pose>
          <geometry>
            <mesh>
              <scale>1 1 1</scale>
              <uri>/home/xzh/MYHTD/nivigation/myh_ws/src/hunter_se/hunter_se_description/meshes/fr_left_link.STL</uri>
            </mesh>
          </geometry>
        </visual>
        <self_collide>0</self_collide>
        <enable_wind>0</enable_wind>
        <kinematic>0</kinematic>
      </link>
      <joint name='fr_steer_right_joint' type='revolute'>
        <pose relative_to='base_link'>0.34219 -0.24619 -0.1535 0 -0 0</pose>
        <parent>base_link</parent>
        <child>fr_steer_right_link</child>
        <axis>
          <xyz>0 0 1</xyz>
          <limit>
            <lower>-0.69</lower>
            <upper>0.69</upper>
            <effort>0</effort>
            <velocity>0</velocity>
          </limit>
          <dynamics>
            <spring_reference>0</spring_reference>
            <spring_stiffness>0</spring_stiffness>
          </dynamics>
        </axis>
      </joint>
      <link name='fr_steer_right_link'>
        <pose relative_to='fr_steer_right_joint'>0 0 0 0 -0 0</pose>
        <inertial>
          <pose>0.000275 -0.016354 -0 0 -0 0</pose>
          <mass>1</mass>
          <inertia>
            <ixx>0.0222</ixx>
            <ixy>0</ixy>
            <ixz>0</ixz>
            <iyy>0.0222</iyy>
            <iyz>0</iyz>
            <izz>0.0378075</izz>
          </inertia>
        </inertial>
        <collision name='fr_steer_right_link_collision'>
          <pose>0 0 0 0 -0 0</pose>
          <geometry>
            <box>
              <size>0.001 0.001 0.001</size>
            </box>
          </geometry>
          <max_contacts>10</max_contacts>
          <surface>
            <contact>
              <ode/>
            </contact>
            <bounce/>
            <friction>
              <torsional>
                <ode/>
              </torsional>
              <ode/>
            </friction>
          </surface>
        </collision>
        <visual name='fr_steer_right_link_visual'>
          <pose>0 0 0 0 -0 0</pose>
          <geometry>
            <box>
              <size>0.001 0.001 0.001</size>
            </box>
          </geometry>
        </visual>
        <self_collide>0</self_collide>
        <enable_wind>0</enable_wind>
        <kinematic>0</kinematic>
      </link>
      <joint name='fr_right_joint' type='revolute'>
        <pose relative_to='fr_steer_right_link'>0 0 0 -1.5708 0 0</pose>
        <parent>fr_steer_right_link</parent>
        <child>fr_right_link</child>
        <axis>
          <xyz>0 0 1</xyz>
          <limit>
            <lower>-1e+16</lower>
            <upper>1e+16</upper>
          </limit>
          <dynamics>
            <spring_reference>0</spring_reference>
            <spring_stiffness>0</spring_stiffness>
          </dynamics>
        </axis>
      </joint>
      <link name='fr_right_link'>
        <pose relative_to='fr_right_joint'>0 0 0 0 -0 0</pose>
        <inertial>
          <pose>0.000275 0 -0.016354 0 -0 0</pose>
          <mass>1</mass>
          <inertia>
            <ixx>0.0222</ixx>
            <ixy>0</ixy>
            <ixz>0</ixz>
            <iyy>0.0222</iyy>
            <iyz>0</iyz>
            <izz>0.0378075</izz>
          </inertia>
        </inertial>
        <collision name='fr_right_link_collision'>
          <pose>0 0 0 0 -0 0</pose>
          <geometry>
            <mesh>
              <scale>1 1 1</scale>
              <uri>/home/xzh/MYHTD/nivigation/myh_ws/src/hunter_se/hunter_se_description/meshes/fr_right_link.STL</uri>
            </mesh>
          </geometry>
          <max_contacts>10</max_contacts>
          <surface>
            <contact>
              <ode/>
            </contact>
            <bounce/>
            <friction>
              <torsional>
                <ode/>
              </torsional>
              <ode/>
            </friction>
          </surface>
        </collision>
        <visual name='fr_right_link_visual'>
          <pose>0 0 0 0 -0 0</pose>
          <geometry>
            <mesh>
              <scale>1 1 1</scale>
              <uri>/home/xzh/MYHTD/nivigation/myh_ws/src/hunter_se/hunter_se_description/meshes/fr_right_link.STL</uri>
            </mesh>
          </geometry>
        </visual>
        <self_collide>0</self_collide>
        <enable_wind>0</enable_wind>
        <kinematic>0</kinematic>
      </link>
      <joint name='front_steer_joint' type='revolute'>
        <pose relative_to='base_link'>0.40792 -1.1e-05 -0.085581 0 -0 0</pose>
        <parent>base_link</parent>
        <child>front_steer_link</child>
        <axis>
          <xyz>0 0 1</xyz>
          <limit>
            <lower>-0.72</lower>
            <upper>0.72</upper>
            <effort>0</effort>
            <velocity>0</velocity>
          </limit>
          <dynamics>
            <spring_reference>0</spring_reference>
            <spring_stiffness>0</spring_stiffness>
          </dynamics>
        </axis>
      </joint>
      <link name='front_steer_link'>
        <pose relative_to='front_steer_joint'>0 0 0 0 -0 0</pose>
        <inertial>
          <pose>0.049836 0 0.017912 0 -0 0</pose>
          <mass>0.0049179</mass>
          <inertia>
            <ixx>1.6846e-07</ixx>
            <ixy>7.6396e-23</ixy>
            <ixz>-1.0974e-08</ixz>
            <iyy>7.549e-07</iyy>
            <iyz>-1.8957e-22</iyz>
            <izz>7.334e-07</izz>
          </inertia>
        </inertial>
        <collision name='front_steer_link_collision'>
          <pose>0 0 0 0 -0 0</pose>
          <geometry>
            <cylinder>
              <length>0.001</length>
              <radius>0.005</radius>
            </cylinder>
          </geometry>
          <max_contacts>10</max_contacts>
          <surface>
            <contact>
              <ode/>
            </contact>
            <bounce/>
            <friction>
              <torsional>
                <ode/>
              </torsional>
              <ode/>
            </friction>
          </surface>
        </collision>
        <visual name='front_steer_link_visual'>
          <pose>0 0 0 0 -0 0</pose>
          <geometry>
            <cylinder>
              <length>0.001</length>
              <radius>0.005</radius>
            </cylinder>
          </geometry>
        </visual>
        <self_collide>0</self_collide>
        <enable_wind>0</enable_wind>
        <kinematic>0</kinematic>
      </link>
      <joint name='re_left_joint' type='revolute'>
        <pose relative_to='base_link'>-0.2078 0.252 -0.158 1.5708 -0 0</pose>
        <parent>base_link</parent>
        <child>re_left_link</child>
        <axis>
          <xyz>0 0 -1</xyz>
          <limit>
            <lower>-1e+16</lower>
            <upper>1e+16</upper>
          </limit>
          <dynamics>
            <spring_reference>0</spring_reference>
            <spring_stiffness>0</spring_stiffness>
          </dynamics>
        </axis>
      </joint>
      <link name='re_left_link'>
        <pose relative_to='re_left_joint'>0 0 0 0 -0 0</pose>
        <inertial>
          <pose>0 2e-06 -0.010284 0 -0 0</pose>
          <mass>1</mass>
          <inertia>
            <ixx>0.0222</ixx>
            <ixy>0</ixy>
            <ixz>0</ixz>
            <iyy>0.0222</iyy>
            <iyz>0</iyz>
            <izz>0.0378075</izz>
          </inertia>
        </inertial>
        <collision name='re_left_link_collision'>
          <pose>0 0 0 0 -0 0</pose>
          <geometry>
            <mesh>
              <scale>1 1 1</scale>
              <uri>/home/xzh/MYHTD/nivigation/myh_ws/src/hunter_se/hunter_se_description/meshes/re_left_link.STL</uri>
            </mesh>
          </geometry>
          <max_contacts>10</max_contacts>
          <surface>
            <contact>
              <ode/>
            </contact>
            <bounce/>
            <friction>
              <torsional>
                <ode/>
              </torsional>
              <ode/>
            </friction>
          </surface>
        </collision>
        <visual name='re_left_link_visual'>
          <pose>0 0 0 0 -0 0</pose>
          <geometry>
            <mesh>
              <scale>1 1 1</scale>
              <uri>/home/xzh/MYHTD/nivigation/myh_ws/src/hunter_se/hunter_se_description/meshes/re_left_link.STL</uri>
            </mesh>
          </geometry>
        </visual>
        <self_collide>0</self_collide>
        <enable_wind>0</enable_wind>
        <kinematic>0</kinematic>
      </link>
      <joint name='re_right_joint' type='revolute'>
        <pose relative_to='base_link'>-0.2078 -0.252 -0.158 -1.5708 0 0</pose>
        <parent>base_link</parent>
        <child>re_right_link</child>
        <axis>
          <xyz>0 0 1</xyz>
          <limit>
            <lower>-1e+16</lower>
            <upper>1e+16</upper>
          </limit>
          <dynamics>
            <spring_reference>0</spring_reference>
            <spring_stiffness>0</spring_stiffness>
          </dynamics>
        </axis>
      </joint>
      <link name='re_right_link'>
        <pose relative_to='re_right_joint'>0 0 0 0 -0 0</pose>
        <inertial>
          <pose>0 0 0 0 -0 0</pose>
          <mass>1</mass>
          <inertia>
            <ixx>0.0222</ixx>
            <ixy>0</ixy>
            <ixz>0</ixz>
            <iyy>0.0222</iyy>
            <iyz>0</iyz>
            <izz>0.0378075</izz>
          </inertia>
        </inertial>
        <collision name='re_right_link_collision'>
          <pose>0 0 0 0 -0 0</pose>
          <geometry>
            <mesh>
              <scale>1 1 1</scale>
              <uri>/home/xzh/MYHTD/nivigation/myh_ws/src/hunter_se/hunter_se_description/meshes/re_right_link.STL</uri>
            </mesh>
          </geometry>
          <max_contacts>10</max_contacts>
          <surface>
            <contact>
              <ode/>
            </contact>
            <bounce/>
            <friction>
              <torsional>
                <ode/>
              </torsional>
              <ode/>
            </friction>
          </surface>
        </collision>
        <visual name='re_right_link_visual'>
          <pose>0 0 0 0 -0 0</pose>
          <geometry>
            <mesh>
              <scale>1 1 1</scale>
              <uri>/home/xzh/MYHTD/nivigation/myh_ws/src/hunter_se/hunter_se_description/meshes/re_right_link.STL</uri>
            </mesh>
          </geometry>
        </visual>
        <self_collide>0</self_collide>
        <enable_wind>0</enable_wind>
        <kinematic>0</kinematic>
      </link>
      <joint name='rear_wheel_joint' type='revolute'>
        <pose relative_to='base_link'>-0.30408 -1.1e-05 -0.085581 0.003231 -0 0</pose>
        <parent>base_link</parent>
        <child>rear_wheel_link</child>
        <axis>
          <xyz>0 0 1</xyz>
          <limit>
            <lower>-1e+16</lower>
            <upper>1e+16</upper>
          </limit>
          <dynamics>
            <spring_reference>0</spring_reference>
            <spring_stiffness>0</spring_stiffness>
          </dynamics>
        </axis>
      </joint>
      <link name='rear_wheel_link'>
        <pose relative_to='rear_wheel_joint'>0 0 0 0 -0 0</pose>
        <inertial>
          <pose>-0.02 0.003127 -0.12735 0 -0 0</pose>
          <mass>0.0049179</mass>
          <inertia>
            <ixx>1.1821e-06</ixx>
            <ixy>9.6965e-13</ixy>
            <ixz>-3.1553e-12</ixz>
            <iyy>9.5276e-07</iyy>
            <iyz>1.2428e-08</iyz>
            <izz>1.0913e-06</izz>
          </inertia>
        </inertial>
        <collision name='rear_wheel_link_collision'>
          <pose>0 0 0 0 -0 0</pose>
          <geometry>
            <cylinder>
              <length>0.001</length>
              <radius>0.005</radius>
            </cylinder>
          </geometry>
          <max_contacts>10</max_contacts>
          <surface>
            <contact>
              <ode/>
            </contact>
            <bounce/>
            <friction>
              <torsional>
                <ode/>
              </torsional>
              <ode/>
            </friction>
          </surface>
        </collision>
        <visual name='rear_wheel_link_visual'>
          <pose>0 0 0 0 -0 0</pose>
          <geometry>
            <cylinder>
              <length>0.001</length>
              <radius>0.005</radius>
            </cylinder>
          </geometry>
        </visual>
        <self_collide>0</self_collide>
        <enable_wind>0</enable_wind>
        <kinematic>0</kinematic>
      </link>
      <plugin name='gazebo_ros_control' filename='libgazebo_ros_control.so'>
        <robotSimType>steer_bot_hardware_gazebo/SteerBotHardwareGazebo</robotSimType>
        <legacyModeNS>0</legacyModeNS>
        <robotNamespace>/car4/</robotNamespace>
      </plugin>
      <plugin name='imu_controller' filename='libhector_gazebo_ros_imu.so'>
        <robotNamespace>car4</robotNamespace>
        <updateRate>50.0</updateRate>
        <bodyName>base_link</bodyName>
        <frameId>car4/base_link</frameId>
        <topicName>imu/data</topicName>
        <accelDrift>0.005 0.005 0.005</accelDrift>
        <accelGaussianNoise>0.005 0.005 0.005</accelGaussianNoise>
        <rateDrift>0.005 0.005 0.005</rateDrift>
        <rateGaussianNoise>0.005 0.005 0.005</rateGaussianNoise>
        <headingDrift>0.005</headingDrift>
        <headingGaussianNoise>0.005</headingGaussianNoise>
      </plugin>
      <static>0</static>
      <plugin name='gps_controller' filename='libhector_gazebo_ros_gps.so'>
        <robotNamespace>car4</robotNamespace>
        <updateRate>40</updateRate>
        <bodyName>base_link</bodyName>
        <frameId>car4/base_link</frameId>
        <topicName>navsat/fix</topicName>
        <velocityTopicName>navsat/vel</velocityTopicName>
        <referenceLatitude>49.9</referenceLatitude>
        <referenceLongitude>8.9</referenceLongitude>
        <referenceHeading>90</referenceHeading>
        <referenceAltitude>0</referenceAltitude>
        <drift>0.0001 0.0001 0.0001</drift>
      </plugin>
      <pose>8 -8 0.36 0 -0 0</pose>
    </model>
  </world>
</sdf>
