<sdf version='1.7'>
  <world name='default'>
    <light name='sun' type='directional'>
      <cast_shadows>1</cast_shadows>
      <pose>0 0 10 0 -0 0</pose>
      <diffuse>0.8 0.8 0.8 1</diffuse>
      <specular>0.2 0.2 0.2 1</specular>
      <attenuation>
        <range>1000</range>
        <constant>0.9</constant>
        <linear>0.01</linear>
        <quadratic>0.001</quadratic>
      </attenuation>
      <direction>-0.5 0.1 -0.9</direction>
      <spot>
        <inner_angle>0</inner_angle>
        <outer_angle>0</outer_angle>
        <falloff>0</falloff>
      </spot>
    </light>
    <model name='ground_plane'>
      <static>1</static>
      <link name='link'>
        <collision name='collision'>
          <geometry>
            <plane>
              <normal>0 0 1</normal>
              <size>100 100</size>
            </plane>
          </geometry>
          <surface>
            <friction>
              <ode>
                <mu>100</mu>
                <mu2>50</mu2>
              </ode>
              <torsional>
                <ode/>
              </torsional>
            </friction>
            <contact>
              <ode/>
            </contact>
            <bounce/>
          </surface>
          <max_contacts>10</max_contacts>
        </collision>
        <visual name='visual'>
          <cast_shadows>0</cast_shadows>
          <geometry>
            <plane>
              <normal>0 0 1</normal>
              <size>100 100</size>
            </plane>
          </geometry>
          <material>
            <script>
              <uri>file://media/materials/scripts/gazebo.material</uri>
              <name>Gazebo/Grey</name>
            </script>
          </material>
        </visual>
        <self_collide>0</self_collide>
        <enable_wind>0</enable_wind>
        <kinematic>0</kinematic>
      </link>
    </model>
    <gravity>0 0 -9.8</gravity>
    <magnetic_field>6e-06 2.3e-05 -4.2e-05</magnetic_field>
    <atmosphere type='adiabatic'/>
    <physics type='ode'>
      <max_step_size>0.01</max_step_size>
      <real_time_factor>1</real_time_factor>
      <real_time_update_rate>100</real_time_update_rate>
    </physics>
    <scene>
      <ambient>0.4 0.4 0.4 1</ambient>
      <background>0.7 0.7 0.7 1</background>
      <shadows>1</shadows>
    </scene>
    <wind/>
    <spherical_coordinates>
      <surface_model>EARTH_WGS84</surface_model>
      <latitude_deg>0</latitude_deg>
      <longitude_deg>0</longitude_deg>
      <elevation>0</elevation>
      <heading_deg>0</heading_deg>
    </spherical_coordinates>
    <state world_name='default'>
      <sim_time>283180 186000000</sim_time>
      <real_time>194 13494141</real_time>
      <wall_time>1709216132 423394761</wall_time>
      <iterations>18307</iterations>
      <model name='car1'>
        <pose>-7.94351 7.86917 0.291216 -0.000347 0.008225 0.190783</pose>
        <scale>1 1 1</scale>
        <link name='base_link'>
          <pose>-7.94351 7.86917 0.291216 -0.000347 0.008225 0.190783</pose>
          <velocity>-0.000223 7.4e-05 0.010805 0.001346 0.001781 -0.003928</velocity>
          <acceleration>-0.307248 -0.110308 9.6736 -0.044599 0.361112 -0.258875</acceleration>
          <wrench>-5.09721 -1.83 160.484 0 -0 0</wrench>
        </link>
        <link name='fr_left_link'>
          <pose>-7.65702 8.17517 0.134701 1.57041 -0.196755 0.209494</pose>
          <velocity>0.000707 -0.000732 0.010136 0.007373 -0.018012 0.160743</velocity>
          <acceleration>-0.297914 -0.158946 9.36795 0.099048 -0.997293 1.92594</acceleration>
          <wrench>-0.297914 -0.158946 9.36795 0 -0 0</wrench>
        </link>
        <link name='fr_right_link'>
          <pose>-7.56212 7.69205 0.135113 -1.57206 1.27426 0.190313</pose>
          <velocity>-0.000946 -0.0008 0.010581 0.003575 0.003463 0.084288</velocity>
          <acceleration>-0.406814 -0.092908 9.76894 0.253786 0.264528 -0.27546</acceleration>
          <wrench>-0.406814 -0.092908 9.76894 0 -0 0</wrench>
        </link>
        <link name='fr_steer_left_link'>
          <pose>-7.65703 8.1752 0.134763 -0.000419 0.008223 0.192449</pose>
          <velocity>0.000775 -0.000803 0.010391 0.002693 0.002139 0.163452</velocity>
          <acceleration>-0.29547 -0.16704 9.39285 -0.229195 0.331036 1.40244</acceleration>
          <wrench>-0.29547 -0.16704 9.39285 0 -0 0</wrench>
        </link>
        <link name='fr_steer_right_link'>
          <pose>-7.56208 7.69208 0.135057 -0.000284 0.008159 0.191518</pose>
          <velocity>-0.001199 -0.001021 0.010268 0.002934 0.002015 0.084289</velocity>
          <acceleration>-0.432044 -0.115061 9.73904 0.162052 0.266018 -0.162381</acceleration>
          <wrench>-0.432044 -0.115061 9.73904 0 -0 0</wrench>
        </link>
        <link name='front_steer_link'>
          <pose>-7.54368 7.94639 0.201908 0.01385 0.008815 0.84001</pose>
          <velocity>0.000797 -0.001385 0.00172 0.100705 0.175418 0.510228</velocity>
          <acceleration>0.115857 -0.185868 7.04857 -1.38355 0.154665 2.11198</acceleration>
          <wrench>0.00057 -0.000914 0.034664 0 -0 0</wrench>
        </link>
        <link name='re_left_link'>
          <pose>-8.19657 8.07695 0.134963 -1.57083 -0.441264 -2.95078</pose>
          <velocity>0.000468 0.000239 0.01235 -0.001872 0.003519 -0.003267</velocity>
          <acceleration>-0.298333 -0.139607 9.85288 -0.35135 0.292377 -0.35352</acceleration>
          <wrench>-0.298333 -0.139607 9.85288 0 -0 0</wrench>
        </link>
        <link name='re_right_link'>
          <pose>-8.10099 7.58209 0.134879 -1.57059 -1.13639 0.190643</pose>
          <velocity>-0.001946 9.4e-05 0.010075 -0.000333 -0.014728 -0.004394</velocity>
          <acceleration>-0.482794 -0.143066 9.71524 -0.339957 -0.794304 -0.54547</acceleration>
          <wrench>-0.482794 -0.143066 9.71524 0 -0 0</wrench>
        </link>
        <link name='rear_wheel_link'>
          <pose>-8.24323 7.81165 0.208242 -0.000117 0.007645 -0.101504</pose>
          <velocity>-0.003101 -0.000408 0.011169 0.039645 -0.001627 -1.90609</velocity>
          <acceleration>-0.44888 0.130537 9.93622 -0.484662 -1.42907 2.78894</acceleration>
          <wrench>-0.002208 0.000642 0.048865 0 -0 0</wrench>
        </link>
      </model>
      <model name='ground_plane'>
        <pose>0 0 0 0 -0 0</pose>
        <scale>1 1 1</scale>
        <link name='link'>
          <pose>0 0 0 0 -0 0</pose>
          <velocity>0 0 0 0 -0 0</velocity>
          <acceleration>0 0 0 0 -0 0</acceleration>
          <wrench>0 0 0 0 -0 0</wrench>
        </link>
      </model>
      <model name='unit_cylinder'>
        <pose>4.34949 -4.88264 0.499096 4.1e-05 5.5e-05 -0.135818</pose>
        <scale>1 1 1</scale>
        <link name='link'>
          <pose>4.34949 -4.88264 0.499096 4.1e-05 5.5e-05 -0.135818</pose>
          <velocity>0 0 0 0 -0 0</velocity>
          <acceleration>0 0 -9.8 0 -0 0</acceleration>
          <wrench>0 0 -9.8 0 -0 0</wrench>
        </link>
      </model>
      <model name='unit_cylinder_0'>
        <pose>5.06568 4.81135 0.499824 -0.000252 -0.000247 0.010197</pose>
        <scale>1 1 1</scale>
        <link name='link'>
          <pose>5.06568 4.81135 0.499824 -0.000252 -0.000247 0.010197</pose>
          <velocity>0 0 0 0 -0 0</velocity>
          <acceleration>-4.34984 4.35027 -0.051026 0.726793 -0.72756 -3.14154</acceleration>
          <wrench>-4.34984 4.35027 -0.051026 0 -0 0</wrench>
        </link>
      </model>
      <model name='unit_cylinder_1'>
        <pose>2.99968 9.00033 0.499096 5e-05 4.7e-05 0.030043</pose>
        <scale>1 1 1</scale>
        <link name='link'>
          <pose>2.99968 9.00033 0.499096 5e-05 4.7e-05 0.030043</pose>
          <velocity>0 0 0 0 -0 0</velocity>
          <acceleration>0 0 -9.8 0 -0 0</acceleration>
          <wrench>0 0 -9.8 0 -0 0</wrench>
        </link>
      </model>
      <model name='unit_cylinder_10'>
        <pose>-0.059009 -0.034612 0.49912 0 0 -2.4e-05</pose>
        <scale>1 1 1</scale>
        <link name='link'>
          <pose>-0.059009 -0.034612 0.49912 0 0 -2.4e-05</pose>
          <velocity>0 0 0 0 -0 0</velocity>
          <acceleration>0 0 -9.8 0 -0 0</acceleration>
          <wrench>0 0 -9.8 0 -0 0</wrench>
        </link>
      </model>
      <model name='unit_cylinder_2'>
        <pose>9.89364 0.025953 0.499096 4.8e-05 4.8e-05 -5e-05</pose>
        <scale>1 1 1</scale>
        <link name='link'>
          <pose>9.89364 0.025953 0.499096 4.8e-05 4.8e-05 -5e-05</pose>
          <velocity>0 0 0 0 -0 0</velocity>
          <acceleration>0 0 -9.8 0 -0 0</acceleration>
          <wrench>0 0 -9.8 0 -0 0</wrench>
        </link>
      </model>
      <model name='unit_cylinder_3'>
        <pose>9.06144 9.12671 0.499789 0.000422 0.000422 -3.9e-05</pose>
        <scale>1 1 1</scale>
        <link name='link'>
          <pose>9.06144 9.12671 0.499789 0.000422 0.000422 -3.9e-05</pose>
          <velocity>0 0 0 0 -0 0</velocity>
          <acceleration>2.11189 -2.11212 -3.11199 1.08259 -1.08223 3.1415</acceleration>
          <wrench>2.11189 -2.11212 -3.11199 0 -0 0</wrench>
        </link>
      </model>
      <model name='unit_cylinder_4'>
        <pose>5.93283 -7.93935 0.49912 0 0 -3.8e-05</pose>
        <scale>1 1 1</scale>
        <link name='link'>
          <pose>5.93283 -7.93935 0.49912 0 0 -3.8e-05</pose>
          <velocity>0 0 0 0 -0 0</velocity>
          <acceleration>0 0 -9.8 0 -0 0</acceleration>
          <wrench>0 0 -9.8 0 -0 0</wrench>
        </link>
      </model>
      <model name='unit_cylinder_5'>
        <pose>-6.97938 -7.90937 0.49912 0 0 -3e-05</pose>
        <scale>1 1 1</scale>
        <link name='link'>
          <pose>-6.97938 -7.90937 0.49912 0 0 -3e-05</pose>
          <velocity>0 0 0 0 -0 0</velocity>
          <acceleration>0 0 -9.8 0 -0 0</acceleration>
          <wrench>0 0 -9.8 0 -0 0</wrench>
        </link>
      </model>
      <model name='unit_cylinder_6'>
        <pose>-9.51363 9.30482 0.499096 4.8e-05 4.8e-05 -2.8e-05</pose>
        <scale>1 1 1</scale>
        <link name='link'>
          <pose>-9.51363 9.30482 0.499096 4.8e-05 4.8e-05 -2.8e-05</pose>
          <velocity>0 0 0 0 -0 0</velocity>
          <acceleration>0 0 -9.8 0 -0 0</acceleration>
          <wrench>0 0 -9.8 0 -0 0</wrench>
        </link>
      </model>
      <model name='unit_cylinder_7'>
        <pose>-4.20166 -4.09739 0.499824 -0.000249 -0.000249 -2.9e-05</pose>
        <scale>1 1 1</scale>
        <link name='link'>
          <pose>-4.20166 -4.09739 0.499824 -0.000249 -0.000249 -2.9e-05</pose>
          <velocity>0 0 0 0 -0 0</velocity>
          <acceleration>-4.34984 4.35027 -0.051026 0.726793 -0.72756 -3.14154</acceleration>
          <wrench>-4.34984 4.35027 -0.051026 0 -0 0</wrench>
        </link>
      </model>
      <model name='unit_cylinder_8'>
        <pose>-3.00007 9.00007 0.49912 0 0 -2.7e-05</pose>
        <scale>1 1 1</scale>
        <link name='link'>
          <pose>-3.00007 9.00007 0.49912 0 0 -2.7e-05</pose>
          <velocity>0 0 0 0 -0 0</velocity>
          <acceleration>0 0 -9.8 0 -0 0</acceleration>
          <wrench>0 0 -9.8 0 -0 0</wrench>
        </link>
      </model>
      <model name='unit_cylinder_9'>
        <pose>-4.10573 4.83475 0.499789 0.000422 0.000422 -2.5e-05</pose>
        <scale>1 1 1</scale>
        <link name='link'>
          <pose>-4.10573 4.83475 0.499789 0.000422 0.000422 -2.5e-05</pose>
          <velocity>0 0 0 0 -0 0</velocity>
          <acceleration>2.11189 -2.11212 -3.11199 1.08259 -1.08223 3.1415</acceleration>
          <wrench>2.11189 -2.11212 -3.11199 0 -0 0</wrench>
        </link>
      </model>
      <light name='sun'>
        <pose>0 0 10 0 -0 0</pose>
      </light>
    </state>
    <gui fullscreen='0'>
      <camera name='user_camera'>
        <pose>0.058001 -19.1471 26.4192 0 0.989798 1.49615</pose>
        <view_controller>orbit</view_controller>
        <projection_type>perspective</projection_type>
      </camera>
    </gui>
    <model name='unit_cylinder'>
      <pose>3.31166 3.10369 0.5 0 -0 0</pose>
      <link name='link'>
        <inertial>
          <mass>1</mass>
          <inertia>
            <ixx>0.145833</ixx>
            <ixy>0</ixy>
            <ixz>0</ixz>
            <iyy>0.145833</iyy>
            <iyz>0</iyz>
            <izz>0.125</izz>
          </inertia>
          <pose>0 0 0 0 -0 0</pose>
        </inertial>
        <collision name='collision'>
          <geometry>
            <cylinder>
              <radius>0.5</radius>
              <length>1</length>
            </cylinder>
          </geometry>
          <max_contacts>10</max_contacts>
          <surface>
            <contact>
              <ode/>
            </contact>
            <bounce/>
            <friction>
              <torsional>
                <ode/>
              </torsional>
              <ode/>
            </friction>
          </surface>
        </collision>
        <visual name='visual'>
          <geometry>
            <cylinder>
              <radius>0.5</radius>
              <length>1</length>
            </cylinder>
          </geometry>
          <material>
            <script>
              <name>Gazebo/Grey</name>
              <uri>file://media/materials/scripts/gazebo.material</uri>
            </script>
          </material>
        </visual>
        <self_collide>0</self_collide>
        <enable_wind>0</enable_wind>
        <kinematic>0</kinematic>
      </link>
    </model>
    <model name='unit_cylinder_0'>
      <pose>6.55696 1.6141 0.5 0 -0 0</pose>
      <link name='link'>
        <inertial>
          <mass>1</mass>
          <inertia>
            <ixx>0.145833</ixx>
            <ixy>0</ixy>
            <ixz>0</ixz>
            <iyy>0.145833</iyy>
            <iyz>0</iyz>
            <izz>0.125</izz>
          </inertia>
          <pose>0 0 0 0 -0 0</pose>
        </inertial>
        <collision name='collision'>
          <geometry>
            <cylinder>
              <radius>0.5</radius>
              <length>1</length>
            </cylinder>
          </geometry>
          <max_contacts>10</max_contacts>
          <surface>
            <contact>
              <ode/>
            </contact>
            <bounce/>
            <friction>
              <torsional>
                <ode/>
              </torsional>
              <ode/>
            </friction>
          </surface>
        </collision>
        <visual name='visual'>
          <geometry>
            <cylinder>
              <radius>0.5</radius>
              <length>1</length>
            </cylinder>
          </geometry>
          <material>
            <script>
              <name>Gazebo/Grey</name>
              <uri>file://media/materials/scripts/gazebo.material</uri>
            </script>
          </material>
        </visual>
        <self_collide>0</self_collide>
        <enable_wind>0</enable_wind>
        <kinematic>0</kinematic>
      </link>
    </model>
    <model name='unit_cylinder_2'>
      <pose>5.48864 -0.040205 0.5 0 -0 0</pose>
      <link name='link'>
        <inertial>
          <mass>1</mass>
          <inertia>
            <ixx>0.145833</ixx>
            <ixy>0</ixy>
            <ixz>0</ixz>
            <iyy>0.145833</iyy>
            <iyz>0</iyz>
            <izz>0.125</izz>
          </inertia>
          <pose>0 0 0 0 -0 0</pose>
        </inertial>
        <collision name='collision'>
          <geometry>
            <cylinder>
              <radius>0.5</radius>
              <length>1</length>
            </cylinder>
          </geometry>
          <max_contacts>10</max_contacts>
          <surface>
            <contact>
              <ode/>
            </contact>
            <bounce/>
            <friction>
              <torsional>
                <ode/>
              </torsional>
              <ode/>
            </friction>
          </surface>
        </collision>
        <visual name='visual'>
          <geometry>
            <cylinder>
              <radius>0.5</radius>
              <length>1</length>
            </cylinder>
          </geometry>
          <material>
            <script>
              <name>Gazebo/Grey</name>
              <uri>file://media/materials/scripts/gazebo.material</uri>
            </script>
          </material>
        </visual>
        <self_collide>0</self_collide>
        <enable_wind>0</enable_wind>
        <kinematic>0</kinematic>
      </link>
    </model>
    <model name='unit_cylinder_1'>
      <pose>-2.24978 2.29542 0.5 0 -0 0</pose>
      <link name='link'>
        <inertial>
          <mass>1</mass>
          <inertia>
            <ixx>0.145833</ixx>
            <ixy>0</ixy>
            <ixz>0</ixz>
            <iyy>0.145833</iyy>
            <iyz>0</iyz>
            <izz>0.125</izz>
          </inertia>
          <pose>0 0 0 0 -0 0</pose>
        </inertial>
        <collision name='collision'>
          <geometry>
            <cylinder>
              <radius>0.5</radius>
              <length>1</length>
            </cylinder>
          </geometry>
          <max_contacts>10</max_contacts>
          <surface>
            <contact>
              <ode/>
            </contact>
            <bounce/>
            <friction>
              <torsional>
                <ode/>
              </torsional>
              <ode/>
            </friction>
          </surface>
        </collision>
        <visual name='visual'>
          <geometry>
            <cylinder>
              <radius>0.5</radius>
              <length>1</length>
            </cylinder>
          </geometry>
          <material>
            <script>
              <name>Gazebo/Grey</name>
              <uri>file://media/materials/scripts/gazebo.material</uri>
            </script>
          </material>
        </visual>
        <self_collide>0</self_collide>
        <enable_wind>0</enable_wind>
        <kinematic>0</kinematic>
      </link>
    </model>
    <model name='unit_cylinder_3'>
      <pose>-1.78977 -0.981187 0.5 0 -0 0</pose>
      <link name='link'>
        <inertial>
          <mass>1</mass>
          <inertia>
            <ixx>0.145833</ixx>
            <ixy>0</ixy>
            <ixz>0</ixz>
            <iyy>0.145833</iyy>
            <iyz>0</iyz>
            <izz>0.125</izz>
          </inertia>
          <pose>0 0 0 0 -0 0</pose>
        </inertial>
        <collision name='collision'>
          <geometry>
            <cylinder>
              <radius>0.5</radius>
              <length>1</length>
            </cylinder>
          </geometry>
          <max_contacts>10</max_contacts>
          <surface>
            <contact>
              <ode/>
            </contact>
            <bounce/>
            <friction>
              <torsional>
                <ode/>
              </torsional>
              <ode/>
            </friction>
          </surface>
        </collision>
        <visual name='visual'>
          <geometry>
            <cylinder>
              <radius>0.5</radius>
              <length>1</length>
            </cylinder>
          </geometry>
          <material>
            <script>
              <name>Gazebo/Grey</name>
              <uri>file://media/materials/scripts/gazebo.material</uri>
            </script>
          </material>
        </visual>
        <self_collide>0</self_collide>
        <enable_wind>0</enable_wind>
        <kinematic>0</kinematic>
      </link>
    </model>
    <model name='unit_cylinder_4'>
      <pose>-3.02115 -1.07237 0.5 0 -0 0</pose>
      <link name='link'>
        <inertial>
          <mass>1</mass>
          <inertia>
            <ixx>0.145833</ixx>
            <ixy>0</ixy>
            <ixz>0</ixz>
            <iyy>0.145833</iyy>
            <iyz>0</iyz>
            <izz>0.125</izz>
          </inertia>
          <pose>0 0 0 0 -0 0</pose>
        </inertial>
        <collision name='collision'>
          <geometry>
            <cylinder>
              <radius>0.5</radius>
              <length>1</length>
            </cylinder>
          </geometry>
          <max_contacts>10</max_contacts>
          <surface>
            <contact>
              <ode/>
            </contact>
            <bounce/>
            <friction>
              <torsional>
                <ode/>
              </torsional>
              <ode/>
            </friction>
          </surface>
        </collision>
        <visual name='visual'>
          <geometry>
            <cylinder>
              <radius>0.5</radius>
              <length>1</length>
            </cylinder>
          </geometry>
          <material>
            <script>
              <name>Gazebo/Grey</name>
              <uri>file://media/materials/scripts/gazebo.material</uri>
            </script>
          </material>
        </visual>
        <self_collide>0</self_collide>
        <enable_wind>0</enable_wind>
        <kinematic>0</kinematic>
      </link>
    </model>
    <model name='unit_cylinder_5'>
      <pose>-7.55826 -2.59755 0.5 0 -0 0</pose>
      <link name='link'>
        <inertial>
          <mass>1</mass>
          <inertia>
            <ixx>0.145833</ixx>
            <ixy>0</ixy>
            <ixz>0</ixz>
            <iyy>0.145833</iyy>
            <iyz>0</iyz>
            <izz>0.125</izz>
          </inertia>
          <pose>0 0 0 0 -0 0</pose>
        </inertial>
        <collision name='collision'>
          <geometry>
            <cylinder>
              <radius>0.5</radius>
              <length>1</length>
            </cylinder>
          </geometry>
          <max_contacts>10</max_contacts>
          <surface>
            <contact>
              <ode/>
            </contact>
            <bounce/>
            <friction>
              <torsional>
                <ode/>
              </torsional>
              <ode/>
            </friction>
          </surface>
        </collision>
        <visual name='visual'>
          <geometry>
            <cylinder>
              <radius>0.5</radius>
              <length>1</length>
            </cylinder>
          </geometry>
          <material>
            <script>
              <name>Gazebo/Grey</name>
              <uri>file://media/materials/scripts/gazebo.material</uri>
            </script>
          </material>
        </visual>
        <self_collide>0</self_collide>
        <enable_wind>0</enable_wind>
        <kinematic>0</kinematic>
      </link>
    </model>
    <model name='unit_cylinder_6'>
      <pose>-12.728 -4.90877 0.5 0 -0 0</pose>
      <link name='link'>
        <inertial>
          <mass>1</mass>
          <inertia>
            <ixx>0.145833</ixx>
            <ixy>0</ixy>
            <ixz>0</ixz>
            <iyy>0.145833</iyy>
            <iyz>0</iyz>
            <izz>0.125</izz>
          </inertia>
          <pose>0 0 0 0 -0 0</pose>
        </inertial>
        <collision name='collision'>
          <geometry>
            <cylinder>
              <radius>0.5</radius>
              <length>1</length>
            </cylinder>
          </geometry>
          <max_contacts>10</max_contacts>
          <surface>
            <contact>
              <ode/>
            </contact>
            <bounce/>
            <friction>
              <torsional>
                <ode/>
              </torsional>
              <ode/>
            </friction>
          </surface>
        </collision>
        <visual name='visual'>
          <geometry>
            <cylinder>
              <radius>0.5</radius>
              <length>1</length>
            </cylinder>
          </geometry>
          <material>
            <script>
              <name>Gazebo/Grey</name>
              <uri>file://media/materials/scripts/gazebo.material</uri>
            </script>
          </material>
        </visual>
        <self_collide>0</self_collide>
        <enable_wind>0</enable_wind>
        <kinematic>0</kinematic>
      </link>
    </model>
    <model name='unit_cylinder_7'>
      <pose>-15.879 2.29168 0.5 0 -0 0</pose>
      <link name='link'>
        <inertial>
          <mass>1</mass>
          <inertia>
            <ixx>0.145833</ixx>
            <ixy>0</ixy>
            <ixz>0</ixz>
            <iyy>0.145833</iyy>
            <iyz>0</iyz>
            <izz>0.125</izz>
          </inertia>
          <pose>0 0 0 0 -0 0</pose>
        </inertial>
        <collision name='collision'>
          <geometry>
            <cylinder>
              <radius>0.5</radius>
              <length>1</length>
            </cylinder>
          </geometry>
          <max_contacts>10</max_contacts>
          <surface>
            <contact>
              <ode/>
            </contact>
            <bounce/>
            <friction>
              <torsional>
                <ode/>
              </torsional>
              <ode/>
            </friction>
          </surface>
        </collision>
        <visual name='visual'>
          <geometry>
            <cylinder>
              <radius>0.5</radius>
              <length>1</length>
            </cylinder>
          </geometry>
          <material>
            <script>
              <name>Gazebo/Grey</name>
              <uri>file://media/materials/scripts/gazebo.material</uri>
            </script>
          </material>
        </visual>
        <self_collide>0</self_collide>
        <enable_wind>0</enable_wind>
        <kinematic>0</kinematic>
      </link>
    </model>
    <model name='unit_cylinder_8'>
      <pose>-12.0474 -2.41547 0.5 0 -0 0</pose>
      <link name='link'>
        <inertial>
          <mass>1</mass>
          <inertia>
            <ixx>0.145833</ixx>
            <ixy>0</ixy>
            <ixz>0</ixz>
            <iyy>0.145833</iyy>
            <iyz>0</iyz>
            <izz>0.125</izz>
          </inertia>
          <pose>0 0 0 0 -0 0</pose>
        </inertial>
        <collision name='collision'>
          <geometry>
            <cylinder>
              <radius>0.5</radius>
              <length>1</length>
            </cylinder>
          </geometry>
          <max_contacts>10</max_contacts>
          <surface>
            <contact>
              <ode/>
            </contact>
            <bounce/>
            <friction>
              <torsional>
                <ode/>
              </torsional>
              <ode/>
            </friction>
          </surface>
        </collision>
        <visual name='visual'>
          <geometry>
            <cylinder>
              <radius>0.5</radius>
              <length>1</length>
            </cylinder>
          </geometry>
          <material>
            <script>
              <name>Gazebo/Grey</name>
              <uri>file://media/materials/scripts/gazebo.material</uri>
            </script>
          </material>
        </visual>
        <self_collide>0</self_collide>
        <enable_wind>0</enable_wind>
        <kinematic>0</kinematic>
      </link>
    </model>
    <model name='unit_cylinder_9'>
      <pose>-11.6482 2.75486 0.5 0 -0 0</pose>
      <link name='link'>
        <inertial>
          <mass>1</mass>
          <inertia>
            <ixx>0.145833</ixx>
            <ixy>0</ixy>
            <ixz>0</ixz>
            <iyy>0.145833</iyy>
            <iyz>0</iyz>
            <izz>0.125</izz>
          </inertia>
          <pose>0 0 0 0 -0 0</pose>
        </inertial>
        <collision name='collision'>
          <geometry>
            <cylinder>
              <radius>0.5</radius>
              <length>1</length>
            </cylinder>
          </geometry>
          <max_contacts>10</max_contacts>
          <surface>
            <contact>
              <ode/>
            </contact>
            <bounce/>
            <friction>
              <torsional>
                <ode/>
              </torsional>
              <ode/>
            </friction>
          </surface>
        </collision>
        <visual name='visual'>
          <geometry>
            <cylinder>
              <radius>0.5</radius>
              <length>1</length>
            </cylinder>
          </geometry>
          <material>
            <script>
              <name>Gazebo/Grey</name>
              <uri>file://media/materials/scripts/gazebo.material</uri>
            </script>
          </material>
        </visual>
        <self_collide>0</self_collide>
        <enable_wind>0</enable_wind>
        <kinematic>0</kinematic>
      </link>
    </model>
    <model name='unit_cylinder_10'>
      <pose>-13.2616 6.11527 0.5 0 -0 0</pose>
      <link name='link'>
        <inertial>
          <mass>1</mass>
          <inertia>
            <ixx>0.145833</ixx>
            <ixy>0</ixy>
            <ixz>0</ixz>
            <iyy>0.145833</iyy>
            <iyz>0</iyz>
            <izz>0.125</izz>
          </inertia>
          <pose>0 0 0 0 -0 0</pose>
        </inertial>
        <collision name='collision'>
          <geometry>
            <cylinder>
              <radius>0.5</radius>
              <length>1</length>
            </cylinder>
          </geometry>
          <max_contacts>10</max_contacts>
          <surface>
            <contact>
              <ode/>
            </contact>
            <bounce/>
            <friction>
              <torsional>
                <ode/>
              </torsional>
              <ode/>
            </friction>
          </surface>
        </collision>
        <visual name='visual'>
          <geometry>
            <cylinder>
              <radius>0.5</radius>
              <length>1</length>
            </cylinder>
          </geometry>
          <material>
            <script>
              <name>Gazebo/Grey</name>
              <uri>file://media/materials/scripts/gazebo.material</uri>
            </script>
          </material>
        </visual>
        <self_collide>0</self_collide>
        <enable_wind>0</enable_wind>
        <kinematic>0</kinematic>
      </link>
    </model>
    <model name='car1'>
      <link name='base_link'>
        <inertial>
          <pose>0.067048 0.007539 0.009259 0 -0 0</pose>
          <mass>16.5899</mass>
          <inertia>
            <ixx>0.350763</ixx>
            <ixy>-0.00589864</ixy>
            <ixz>-0.0572654</ixz>
            <iyy>0.484467</iyy>
            <iyz>-0.0164022</iyz>
            <izz>0.407071</izz>
          </inertia>
        </inertial>
        <collision name='base_link_collision'>
          <pose>0 0 0 0 -0 0</pose>
          <geometry>
            <mesh>
              <scale>1 1 1</scale>
              <uri>/home/xzh/MYHTD/nivigation/myh_ws/src/hunter_se/hunter_se_description/meshes/base_link.STL</uri>
            </mesh>
          </geometry>
          <max_contacts>10</max_contacts>
          <surface>
            <contact>
              <ode/>
            </contact>
            <bounce/>
            <friction>
              <torsional>
                <ode/>
              </torsional>
              <ode/>
            </friction>
          </surface>
        </collision>
        <collision name='base_link_fixed_joint_lump__box_link_collision_1'>
          <pose>0.2 0 0.02 0 -0 0</pose>
          <geometry>
            <mesh>
              <scale>1 1 1</scale>
              <uri>/home/xzh/MYHTD/nivigation/myh_ws/src/hunter_se/hunter_se_description/meshes/box_link.STL</uri>
            </mesh>
          </geometry>
          <max_contacts>10</max_contacts>
          <surface>
            <contact>
              <ode/>
            </contact>
            <bounce/>
            <friction>
              <torsional>
                <ode/>
              </torsional>
              <ode/>
            </friction>
          </surface>
        </collision>
        <collision name='base_link_fixed_joint_lump__laser_livox_collision_2'>
          <pose>0.46 0 0.09 0 -0 0</pose>
          <geometry>
            <box>
              <size>0.01 0.01 0.01</size>
            </box>
          </geometry>
          <surface>
            <contact>
              <ode/>
            </contact>
            <friction>
              <ode/>
              <torsional>
                <ode/>
              </torsional>
            </friction>
            <bounce/>
          </surface>
          <max_contacts>10</max_contacts>
        </collision>
        <visual name='base_link_visual'>
          <pose>0 0 0 0 -0 0</pose>
          <geometry>
            <mesh>
              <scale>1 1 1</scale>
              <uri>/home/xzh/MYHTD/nivigation/myh_ws/src/hunter_se/hunter_se_description/meshes/base_link.STL</uri>
            </mesh>
          </geometry>
        </visual>
        <visual name='base_link_fixed_joint_lump__box_link_visual_1'>
          <pose>0.2 0 0.02 0 -0 0</pose>
          <geometry>
            <mesh>
              <scale>1 1 1</scale>
              <uri>/home/xzh/MYHTD/nivigation/myh_ws/src/hunter_se/hunter_se_description/meshes/box_link.STL</uri>
            </mesh>
          </geometry>
        </visual>
        <visual name='base_link_fixed_joint_lump__laser_livox_visual_2'>
          <pose>0.46 0 0.09 0 -0 0</pose>
          <geometry>
            <box>
              <size>0.01 0.01 0.01</size>
            </box>
          </geometry>
        </visual>
        <sensor name='car1/laser_livox' type='ray'>
          <visualize>1</visualize>
          <update_rate>100</update_rate>
          <plugin name='gazebo_ros_laser_controller' filename='liblivox_laser_simulation.so'>
            <ray>
              <scan>
                <horizontal>
                  <samples>100</samples>
                  <resolution>1</resolution>
                  <min_angle>-0.6143553777777778</min_angle>
                  <max_angle>0.6143553777777778</max_angle>
                </horizontal>
                <vertical>
                  <samples>50</samples>
                  <resolution>1</resolution>
                  <min_angle>-0.6143553777777778</min_angle>
                  <max_angle>0.6143553777777778</max_angle>
                </vertical>
              </scan>
              <range>
                <min>0.1</min>
                <max>200</max>
                <resolution>0.002</resolution>
              </range>
              <noise>
                <type>gaussian</type>
                <mean>0.0</mean>
                <stddev>0.01</stddev>
              </noise>
            </ray>
            <visualize>0</visualize>
            <samples>10000</samples>
            <downsample>1</downsample>
            <csv_file_name>/home/xzh/MYHTD/nivigation/myh_ws/src/livox_laser_simulation/scan_mode/mid70.csv</csv_file_name>
            <ros_topic>car1/scan</ros_topic>
            <robotNamespace>/car1/</robotNamespace>
          </plugin>
          <pose>0.46 0 0.09 0 -0 0</pose>
          <ray>
            <scan>
              <horizontal>
                <samples>640</samples>
                <resolution>1</resolution>
                <min_angle>0</min_angle>
                <max_angle>0</max_angle>
              </horizontal>
              <vertical>
                <samples>1</samples>
                <min_angle>0</min_angle>
                <max_angle>0</max_angle>
              </vertical>
            </scan>
            <range>
              <min>0</min>
              <max>0</max>
            </range>
          </ray>
        </sensor>
        <self_collide>0</self_collide>
        <enable_wind>0</enable_wind>
        <kinematic>0</kinematic>
      </link>
      <joint name='fr_steer_left_joint' type='revolute'>
        <pose relative_to='base_link'>0.34058 0.24619 -0.1535 0 -0 0</pose>
        <parent>base_link</parent>
        <child>fr_steer_left_link</child>
        <axis>
          <xyz>0 0 1</xyz>
          <limit>
            <lower>-0.69</lower>
            <upper>0.69</upper>
            <effort>0</effort>
            <velocity>0</velocity>
          </limit>
          <dynamics>
            <spring_reference>0</spring_reference>
            <spring_stiffness>0</spring_stiffness>
          </dynamics>
        </axis>
      </joint>
      <link name='fr_steer_left_link'>
        <pose relative_to='fr_steer_left_joint'>0 0 0 0 -0 0</pose>
        <inertial>
          <pose>-0.000278 0.016354 0 0 -0 0</pose>
          <mass>1</mass>
          <inertia>
            <ixx>0.0222</ixx>
            <ixy>0</ixy>
            <ixz>0</ixz>
            <iyy>0.0222</iyy>
            <iyz>0</iyz>
            <izz>0.0378075</izz>
          </inertia>
        </inertial>
        <collision name='fr_steer_left_link_collision'>
          <pose>0 0 0 0 -0 0</pose>
          <geometry>
            <box>
              <size>0.001 0.001 0.001</size>
            </box>
          </geometry>
          <max_contacts>10</max_contacts>
          <surface>
            <contact>
              <ode/>
            </contact>
            <bounce/>
            <friction>
              <torsional>
                <ode/>
              </torsional>
              <ode/>
            </friction>
          </surface>
        </collision>
        <visual name='fr_steer_left_link_visual'>
          <pose>0 0 0 0 -0 0</pose>
          <geometry>
            <box>
              <size>0.001 0.001 0.001</size>
            </box>
          </geometry>
        </visual>
        <self_collide>0</self_collide>
        <enable_wind>0</enable_wind>
        <kinematic>0</kinematic>
      </link>
      <joint name='fr_left_joint' type='revolute'>
        <pose relative_to='fr_steer_left_link'>0 0 0 1.5708 -0 0.016976</pose>
        <parent>fr_steer_left_link</parent>
        <child>fr_left_link</child>
        <axis>
          <xyz>0 0 -1</xyz>
          <limit>
            <lower>-1e+16</lower>
            <upper>1e+16</upper>
          </limit>
          <dynamics>
            <spring_reference>0</spring_reference>
            <spring_stiffness>0</spring_stiffness>
          </dynamics>
        </axis>
      </joint>
      <link name='fr_left_link'>
        <pose relative_to='fr_left_joint'>0 0 0 0 -0 0</pose>
        <inertial>
          <pose>-0 0 -0.016356 0 -0 0</pose>
          <mass>1</mass>
          <inertia>
            <ixx>0.0222</ixx>
            <ixy>0</ixy>
            <ixz>0</ixz>
            <iyy>0.0222</iyy>
            <iyz>0</iyz>
            <izz>0.0378075</izz>
          </inertia>
        </inertial>
        <collision name='fr_left_link_collision'>
          <pose>0 0 0 0 -0 0</pose>
          <geometry>
            <mesh>
              <scale>1 1 1</scale>
              <uri>/home/xzh/MYHTD/nivigation/myh_ws/src/hunter_se/hunter_se_description/meshes/fr_left_link.STL</uri>
            </mesh>
          </geometry>
          <max_contacts>10</max_contacts>
          <surface>
            <contact>
              <ode/>
            </contact>
            <bounce/>
            <friction>
              <torsional>
                <ode/>
              </torsional>
              <ode/>
            </friction>
          </surface>
        </collision>
        <visual name='fr_left_link_visual'>
          <pose>0 0 0 0 -0 0</pose>
          <geometry>
            <mesh>
              <scale>1 1 1</scale>
              <uri>/home/xzh/MYHTD/nivigation/myh_ws/src/hunter_se/hunter_se_description/meshes/fr_left_link.STL</uri>
            </mesh>
          </geometry>
        </visual>
        <self_collide>0</self_collide>
        <enable_wind>0</enable_wind>
        <kinematic>0</kinematic>
      </link>
      <joint name='fr_steer_right_joint' type='revolute'>
        <pose relative_to='base_link'>0.34219 -0.24619 -0.1535 0 -0 0</pose>
        <parent>base_link</parent>
        <child>fr_steer_right_link</child>
        <axis>
          <xyz>0 0 1</xyz>
          <limit>
            <lower>-0.69</lower>
            <upper>0.69</upper>
            <effort>0</effort>
            <velocity>0</velocity>
          </limit>
          <dynamics>
            <spring_reference>0</spring_reference>
            <spring_stiffness>0</spring_stiffness>
          </dynamics>
        </axis>
      </joint>
      <link name='fr_steer_right_link'>
        <pose relative_to='fr_steer_right_joint'>0 0 0 0 -0 0</pose>
        <inertial>
          <pose>0.000275 -0.016354 -0 0 -0 0</pose>
          <mass>1</mass>
          <inertia>
            <ixx>0.0222</ixx>
            <ixy>0</ixy>
            <ixz>0</ixz>
            <iyy>0.0222</iyy>
            <iyz>0</iyz>
            <izz>0.0378075</izz>
          </inertia>
        </inertial>
        <collision name='fr_steer_right_link_collision'>
          <pose>0 0 0 0 -0 0</pose>
          <geometry>
            <box>
              <size>0.001 0.001 0.001</size>
            </box>
          </geometry>
          <max_contacts>10</max_contacts>
          <surface>
            <contact>
              <ode/>
            </contact>
            <bounce/>
            <friction>
              <torsional>
                <ode/>
              </torsional>
              <ode/>
            </friction>
          </surface>
        </collision>
        <visual name='fr_steer_right_link_visual'>
          <pose>0 0 0 0 -0 0</pose>
          <geometry>
            <box>
              <size>0.001 0.001 0.001</size>
            </box>
          </geometry>
        </visual>
        <self_collide>0</self_collide>
        <enable_wind>0</enable_wind>
        <kinematic>0</kinematic>
      </link>
      <joint name='fr_right_joint' type='revolute'>
        <pose relative_to='fr_steer_right_link'>0 0 0 -1.5708 0 0</pose>
        <parent>fr_steer_right_link</parent>
        <child>fr_right_link</child>
        <axis>
          <xyz>0 0 1</xyz>
          <limit>
            <lower>-1e+16</lower>
            <upper>1e+16</upper>
          </limit>
          <dynamics>
            <spring_reference>0</spring_reference>
            <spring_stiffness>0</spring_stiffness>
          </dynamics>
        </axis>
      </joint>
      <link name='fr_right_link'>
        <pose relative_to='fr_right_joint'>0 0 0 0 -0 0</pose>
        <inertial>
          <pose>0.000275 0 -0.016354 0 -0 0</pose>
          <mass>1</mass>
          <inertia>
            <ixx>0.0222</ixx>
            <ixy>0</ixy>
            <ixz>0</ixz>
            <iyy>0.0222</iyy>
            <iyz>0</iyz>
            <izz>0.0378075</izz>
          </inertia>
        </inertial>
        <collision name='fr_right_link_collision'>
          <pose>0 0 0 0 -0 0</pose>
          <geometry>
            <mesh>
              <scale>1 1 1</scale>
              <uri>/home/xzh/MYHTD/nivigation/myh_ws/src/hunter_se/hunter_se_description/meshes/fr_right_link.STL</uri>
            </mesh>
          </geometry>
          <max_contacts>10</max_contacts>
          <surface>
            <contact>
              <ode/>
            </contact>
            <bounce/>
            <friction>
              <torsional>
                <ode/>
              </torsional>
              <ode/>
            </friction>
          </surface>
        </collision>
        <visual name='fr_right_link_visual'>
          <pose>0 0 0 0 -0 0</pose>
          <geometry>
            <mesh>
              <scale>1 1 1</scale>
              <uri>/home/xzh/MYHTD/nivigation/myh_ws/src/hunter_se/hunter_se_description/meshes/fr_right_link.STL</uri>
            </mesh>
          </geometry>
        </visual>
        <self_collide>0</self_collide>
        <enable_wind>0</enable_wind>
        <kinematic>0</kinematic>
      </link>
      <joint name='front_steer_joint' type='revolute'>
        <pose relative_to='base_link'>0.40792 -1.1e-05 -0.085581 0 -0 0</pose>
        <parent>base_link</parent>
        <child>front_steer_link</child>
        <axis>
          <xyz>0 0 1</xyz>
          <limit>
            <lower>-0.72</lower>
            <upper>0.72</upper>
            <effort>0</effort>
            <velocity>0</velocity>
          </limit>
          <dynamics>
            <spring_reference>0</spring_reference>
            <spring_stiffness>0</spring_stiffness>
          </dynamics>
        </axis>
      </joint>
      <link name='front_steer_link'>
        <pose relative_to='front_steer_joint'>0 0 0 0 -0 0</pose>
        <inertial>
          <pose>0.049836 0 0.017912 0 -0 0</pose>
          <mass>0.0049179</mass>
          <inertia>
            <ixx>1.6846e-07</ixx>
            <ixy>7.6396e-23</ixy>
            <ixz>-1.0974e-08</ixz>
            <iyy>7.549e-07</iyy>
            <iyz>-1.8957e-22</iyz>
            <izz>7.334e-07</izz>
          </inertia>
        </inertial>
        <collision name='front_steer_link_collision'>
          <pose>0 0 0 0 -0 0</pose>
          <geometry>
            <cylinder>
              <length>0.001</length>
              <radius>0.005</radius>
            </cylinder>
          </geometry>
          <max_contacts>10</max_contacts>
          <surface>
            <contact>
              <ode/>
            </contact>
            <bounce/>
            <friction>
              <torsional>
                <ode/>
              </torsional>
              <ode/>
            </friction>
          </surface>
        </collision>
        <visual name='front_steer_link_visual'>
          <pose>0 0 0 0 -0 0</pose>
          <geometry>
            <cylinder>
              <length>0.001</length>
              <radius>0.005</radius>
            </cylinder>
          </geometry>
        </visual>
        <self_collide>0</self_collide>
        <enable_wind>0</enable_wind>
        <kinematic>0</kinematic>
      </link>
      <joint name='re_left_joint' type='revolute'>
        <pose relative_to='base_link'>-0.2078 0.252 -0.158 1.5708 -0 0</pose>
        <parent>base_link</parent>
        <child>re_left_link</child>
        <axis>
          <xyz>0 0 -1</xyz>
          <limit>
            <lower>-1e+16</lower>
            <upper>1e+16</upper>
          </limit>
          <dynamics>
            <spring_reference>0</spring_reference>
            <spring_stiffness>0</spring_stiffness>
          </dynamics>
        </axis>
      </joint>
      <link name='re_left_link'>
        <pose relative_to='re_left_joint'>0 0 0 0 -0 0</pose>
        <inertial>
          <pose>0 2e-06 -0.010284 0 -0 0</pose>
          <mass>1</mass>
          <inertia>
            <ixx>0.0222</ixx>
            <ixy>0</ixy>
            <ixz>0</ixz>
            <iyy>0.0222</iyy>
            <iyz>0</iyz>
            <izz>0.0378075</izz>
          </inertia>
        </inertial>
        <collision name='re_left_link_collision'>
          <pose>0 0 0 0 -0 0</pose>
          <geometry>
            <mesh>
              <scale>1 1 1</scale>
              <uri>/home/xzh/MYHTD/nivigation/myh_ws/src/hunter_se/hunter_se_description/meshes/re_left_link.STL</uri>
            </mesh>
          </geometry>
          <max_contacts>10</max_contacts>
          <surface>
            <contact>
              <ode/>
            </contact>
            <bounce/>
            <friction>
              <torsional>
                <ode/>
              </torsional>
              <ode/>
            </friction>
          </surface>
        </collision>
        <visual name='re_left_link_visual'>
          <pose>0 0 0 0 -0 0</pose>
          <geometry>
            <mesh>
              <scale>1 1 1</scale>
              <uri>/home/xzh/MYHTD/nivigation/myh_ws/src/hunter_se/hunter_se_description/meshes/re_left_link.STL</uri>
            </mesh>
          </geometry>
        </visual>
        <self_collide>0</self_collide>
        <enable_wind>0</enable_wind>
        <kinematic>0</kinematic>
      </link>
      <joint name='re_right_joint' type='revolute'>
        <pose relative_to='base_link'>-0.2078 -0.252 -0.158 -1.5708 0 0</pose>
        <parent>base_link</parent>
        <child>re_right_link</child>
        <axis>
          <xyz>0 0 1</xyz>
          <limit>
            <lower>-1e+16</lower>
            <upper>1e+16</upper>
          </limit>
          <dynamics>
            <spring_reference>0</spring_reference>
            <spring_stiffness>0</spring_stiffness>
          </dynamics>
        </axis>
      </joint>
      <link name='re_right_link'>
        <pose relative_to='re_right_joint'>0 0 0 0 -0 0</pose>
        <inertial>
          <pose>0 0 0 0 -0 0</pose>
          <mass>1</mass>
          <inertia>
            <ixx>0.0222</ixx>
            <ixy>0</ixy>
            <ixz>0</ixz>
            <iyy>0.0222</iyy>
            <iyz>0</iyz>
            <izz>0.0378075</izz>
          </inertia>
        </inertial>
        <collision name='re_right_link_collision'>
          <pose>0 0 0 0 -0 0</pose>
          <geometry>
            <mesh>
              <scale>1 1 1</scale>
              <uri>/home/xzh/MYHTD/nivigation/myh_ws/src/hunter_se/hunter_se_description/meshes/re_right_link.STL</uri>
            </mesh>
          </geometry>
          <max_contacts>10</max_contacts>
          <surface>
            <contact>
              <ode/>
            </contact>
            <bounce/>
            <friction>
              <torsional>
                <ode/>
              </torsional>
              <ode/>
            </friction>
          </surface>
        </collision>
        <visual name='re_right_link_visual'>
          <pose>0 0 0 0 -0 0</pose>
          <geometry>
            <mesh>
              <scale>1 1 1</scale>
              <uri>/home/xzh/MYHTD/nivigation/myh_ws/src/hunter_se/hunter_se_description/meshes/re_right_link.STL</uri>
            </mesh>
          </geometry>
        </visual>
        <self_collide>0</self_collide>
        <enable_wind>0</enable_wind>
        <kinematic>0</kinematic>
      </link>
      <joint name='rear_wheel_joint' type='revolute'>
        <pose relative_to='base_link'>-0.30408 -1.1e-05 -0.085581 0.003231 -0 0</pose>
        <parent>base_link</parent>
        <child>rear_wheel_link</child>
        <axis>
          <xyz>0 0 1</xyz>
          <limit>
            <lower>-1e+16</lower>
            <upper>1e+16</upper>
          </limit>
          <dynamics>
            <spring_reference>0</spring_reference>
            <spring_stiffness>0</spring_stiffness>
          </dynamics>
        </axis>
      </joint>
      <link name='rear_wheel_link'>
        <pose relative_to='rear_wheel_joint'>0 0 0 0 -0 0</pose>
        <inertial>
          <pose>-0.02 0.003127 -0.12735 0 -0 0</pose>
          <mass>0.0049179</mass>
          <inertia>
            <ixx>1.1821e-06</ixx>
            <ixy>9.6965e-13</ixy>
            <ixz>-3.1553e-12</ixz>
            <iyy>9.5276e-07</iyy>
            <iyz>1.2428e-08</iyz>
            <izz>1.0913e-06</izz>
          </inertia>
        </inertial>
        <collision name='rear_wheel_link_collision'>
          <pose>0 0 0 0 -0 0</pose>
          <geometry>
            <cylinder>
              <length>0.001</length>
              <radius>0.005</radius>
            </cylinder>
          </geometry>
          <max_contacts>10</max_contacts>
          <surface>
            <contact>
              <ode/>
            </contact>
            <bounce/>
            <friction>
              <torsional>
                <ode/>
              </torsional>
              <ode/>
            </friction>
          </surface>
        </collision>
        <visual name='rear_wheel_link_visual'>
          <pose>0 0 0 0 -0 0</pose>
          <geometry>
            <cylinder>
              <length>0.001</length>
              <radius>0.005</radius>
            </cylinder>
          </geometry>
        </visual>
        <self_collide>0</self_collide>
        <enable_wind>0</enable_wind>
        <kinematic>0</kinematic>
      </link>
      <plugin name='gazebo_ros_control' filename='libgazebo_ros_control.so'>
        <robotSimType>steer_bot_hardware_gazebo/SteerBotHardwareGazebo</robotSimType>
        <legacyModeNS>0</legacyModeNS>
        <robotNamespace>/car1/</robotNamespace>
      </plugin>
      <plugin name='imu_controller' filename='libhector_gazebo_ros_imu.so'>
        <robotNamespace>car1</robotNamespace>
        <updateRate>50.0</updateRate>
        <bodyName>base_link</bodyName>
        <frameId>car1/base_link</frameId>
        <topicName>imu/data</topicName>
        <accelDrift>0.005 0.005 0.005</accelDrift>
        <accelGaussianNoise>0.005 0.005 0.005</accelGaussianNoise>
        <rateDrift>0.005 0.005 0.005</rateDrift>
        <rateGaussianNoise>0.005 0.005 0.005</rateGaussianNoise>
        <headingDrift>0.005</headingDrift>
        <headingGaussianNoise>0.005</headingGaussianNoise>
      </plugin>
      <static>0</static>
      <plugin name='gps_controller' filename='libhector_gazebo_ros_gps.so'>
        <robotNamespace>car1</robotNamespace>
        <updateRate>40</updateRate>
        <bodyName>base_link</bodyName>
        <frameId>car1/base_link</frameId>
        <topicName>navsat/fix</topicName>
        <velocityTopicName>navsat/vel</velocityTopicName>
        <referenceLatitude>49.9</referenceLatitude>
        <referenceLongitude>8.9</referenceLongitude>
        <referenceHeading>90</referenceHeading>
        <referenceAltitude>0</referenceAltitude>
        <drift>0.0001 0.0001 0.0001</drift>
      </plugin>
      <pose>-8 8 0.4 0 -0 0</pose>
    </model>
  </world>
</sdf>
